Workbook

Sheet formated
A1: Collaborator | B1: Project | C1: Sample_ID | D1: Plate_ID | E1: Sample_Name | F1: Well | G1: Sample # | H1: Trait | I1: Pedigree | J1: Generation | K1: Organism | L1: Comments | M1: PlantSource | N1: plant_id | O1: plant_name | P1: plot_name | Q1: accession_name | R1: plot_number | S1: block_number | T1: is_a_control | U1: rep_number | V1: row_number | W1: col_number | X1: plant_number | Y1: Cross Combination
A2: Jannink | B2: USDA-Ithaca2025-O3K_01-07 | C2: 753635 | D2: 1 | E2: =O2 -> CU_ARS_2025_WOF_P_10_plant_1 | F2: A01 | G2: 1 | I2: AURORA | J2: P | N2: =VLOOKUP(C2,CU_ARS_2025_WOF_F2!$A$2:$K$673,2,FALSE) -> CU_ARS_2025_WOF_P_10_plant_1 | O2: =VLOOKUP(C2,CU_ARS_2025_WOF_F2!$A$2:$K$673,2,FALSE) -> CU_ARS_2025_WOF_P_10_plant_1 | P2: =VLOOKUP(C2,CU_ARS_2025_WOF_F2!$A$2:$K$673,3,FALSE) -> CU_ARS_2025_WOF_P_10 | Q2: =VLOOKUP(C2,CU_ARS_2025_WOF_F2!$A$2:$K$673,4,FALSE) -> AURORA | R2: =VLOOKUP(C2,CU_ARS_2025_WOF_F2!$A$2:$K$673,5,FALSE) -> 10 | S2: =VLOOKUP(C2,CU_ARS_2025_WOF_F2!$A$2:$K$673,6,FALSE) -> 1 | T2: =VLOOKUP(C2,CU_ARS_2025_WOF_F2!$A$2:$K$673,7,FALSE) -> 0 | U2: =VLOOKUP(C2,CU_ARS_2025_WOF_F2!$A$2:$K$673,8,FALSE) -> 1 | V2: =VLOOKUP(C2,CU_ARS_2025_WOF_F2!$A$2:$K$673,9,FALSE) -> 0 | W2: =VLOOKUP(C2,CU_ARS_2025_WOF_F2!$A$2:$K$673,10,FALSE) -> 0 | X2: =VLOOKUP(C2,CU_ARS_2025_WOF_F2!$A$2:$K$673,11,FALSE) -> 1 | Y2: AURORA
A3: Jannink | B3: USDA-Ithaca2025-O3K_01-07 | C3: 753857 | D3: 1 | E3: =O3 -> CU_ARS_2025_WOF_P_11_plant_3 | F3: B01 | G3: 2 | I3: AWNLESS_CURLED | J3: P | N3: =VLOOKUP(C3,CU_ARS_2025_WOF_F2!$A$2:$K$673,2,FALSE) -> CU_ARS_2025_WOF_P_11_plant_3 | O3: =VLOOKUP(C3,CU_ARS_2025_WOF_F2!$A$2:$K$673,2,FALSE) -> CU_ARS_2025_WOF_P_11_plant_3 | P3: =VLOOKUP(C3,CU_ARS_2025_WOF_F2!$A$2:$K$673,3,FALSE) -> CU_ARS_2025_WOF_P_11 | Q3: =VLOOKUP(C3,CU_ARS_2025_WOF_F2!$A$2:$K$673,4,FALSE) -> AWNLESS_CURLED | R3: =VLOOKUP(C3,CU_ARS_2025_WOF_F2!$A$2:$K$673,5,FALSE) -> 11 | S3: =VLOOKUP(C3,CU_ARS_2025_WOF_F2!$A$2:$K$673,6,FALSE) -> 1 | T3: =VLOOKUP(C3,CU_ARS_2025_WOF_F2!$A$2:$K$673,7,FALSE) -> 0 | U3: =VLOOKUP(C3,CU_ARS_2025_WOF_F2!$A$2:$K$673,8,FALSE) -> 1 | V3: =VLOOKUP(C3,CU_ARS_2025_WOF_F2!$A$2:$K$673,9,FALSE) -> 0 | W3: =VLOOKUP(C3,CU_ARS_2025_WOF_F2!$A$2:$K$673,10,FALSE) -> 0 | X3: =VLOOKUP(C3,CU_ARS_2025_WOF_F2!$A$2:$K$673,11,FALSE) -> 3 | Y3: AWNLESS_CURLED
A4: Jannink | B4: USDA-Ithaca2025-O3K_01-07 | C4: 754009 | D4: 1 | E4: =O4 -> CU_ARS_2025_WOF_P_12_plant_1 | F4: C01 | G4: 3 | I4: Gerard 227 | J4: P | N4: =VLOOKUP(C4,CU_ARS_2025_WOF_F2!$A$2:$K$673,2,FALSE) -> CU_ARS_2025_WOF_P_12_plant_1 | O4: =VLOOKUP(C4,CU_ARS_2025_WOF_F2!$A$2:$K$673,2,FALSE) -> CU_ARS_2025_WOF_P_12_plant_1 | P4: =VLOOKUP(C4,CU_ARS_2025_WOF_F2!$A$2:$K$673,3,FALSE) -> CU_ARS_2025_WOF_P_12 | Q4: =VLOOKUP(C4,CU_ARS_2025_WOF_F2!$A$2:$K$673,4,FALSE) -> Gerard 227 | R4: =VLOOKUP(C4,CU_ARS_2025_WOF_F2!$A$2:$K$673,5,FALSE) -> 12 | S4: =VLOOKUP(C4,CU_ARS_2025_WOF_F2!$A$2:$K$673,6,FALSE) -> 1 | T4: =VLOOKUP(C4,CU_ARS_2025_WOF_F2!$A$2:$K$673,7,FALSE) -> 0 | U4: =VLOOKUP(C4,CU_ARS_2025_WOF_F2!$A$2:$K$673,8,FALSE) -> 1 | V4: =VLOOKUP(C4,CU_ARS_2025_WOF_F2!$A$2:$K$673,9,FALSE) -> 0 | W4: =VLOOKUP(C4,CU_ARS_2025_WOF_F2!$A$2:$K$673,10,FALSE) -> 0 | X4: =VLOOKUP(C4,CU_ARS_2025_WOF_F2!$A$2:$K$673,11,FALSE) -> 1 | Y4: Gerard 227
A5: Jannink | B5: USDA-Ithaca2025-O3K_01-07 | C5: 754008 | D5: 1 | E5: =O5 -> CU_ARS_2025_WOF_P_13_plant_3 | F5: D01 | G5: 4 | I5: NC20-4452 | J5: P | N5: =VLOOKUP(C5,CU_ARS_2025_WOF_F2!$A$2:$K$673,2,FALSE) -> CU_ARS_2025_WOF_P_13_plant_3 | O5: =VLOOKUP(C5,CU_ARS_2025_WOF_F2!$A$2:$K$673,2,FALSE) -> CU_ARS_2025_WOF_P_13_plant_3 | P5: =VLOOKUP(C5,CU_ARS_2025_WOF_F2!$A$2:$K$673,3,FALSE) -> CU_ARS_2025_WOF_P_13 | Q5: =VLOOKUP(C5,CU_ARS_2025_WOF_F2!$A$2:$K$673,4,FALSE) -> NC20-4452 | R5: =VLOOKUP(C5,CU_ARS_2025_WOF_F2!$A$2:$K$673,5,FALSE) -> 13 | S5: =VLOOKUP(C5,CU_ARS_2025_WOF_F2!$A$2:$K$673,6,FALSE) -> 1 | T5: =VLOOKUP(C5,CU_ARS_2025_WOF_F2!$A$2:$K$673,7,FALSE) -> 0 | U5: =VLOOKUP(C5,CU_ARS_2025_WOF_F2!$A$2:$K$673,8,FALSE) -> 1 | V5: =VLOOKUP(C5,CU_ARS_2025_WOF_F2!$A$2:$K$673,9,FALSE) -> 0 | W5: =VLOOKUP(C5,CU_ARS_2025_WOF_F2!$A$2:$K$673,10,FALSE) -> 0 | X5: =VLOOKUP(C5,CU_ARS_2025_WOF_F2!$A$2:$K$673,11,FALSE) -> 3 | Y5: NC20-4452
A6: Jannink | B6: USDA-Ithaca2025-O3K_01-07 | C6: 754005 | D6: 1 | E6: =O6 -> CU_ARS_2025_WOF_P_14_plant_3 | F6: E01 | G6: 5 | I6: NC20-4526 | J6: P | N6: =VLOOKUP(C6,CU_ARS_2025_WOF_F2!$A$2:$K$673,2,FALSE) -> CU_ARS_2025_WOF_P_14_plant_3 | O6: =VLOOKUP(C6,CU_ARS_2025_WOF_F2!$A$2:$K$673,2,FALSE) -> CU_ARS_2025_WOF_P_14_plant_3 | P6: =VLOOKUP(C6,CU_ARS_2025_WOF_F2!$A$2:$K$673,3,FALSE) -> CU_ARS_2025_WOF_P_14 | Q6: =VLOOKUP(C6,CU_ARS_2025_WOF_F2!$A$2:$K$673,4,FALSE) -> NC20-4526 | R6: =VLOOKUP(C6,CU_ARS_2025_WOF_F2!$A$2:$K$673,5,FALSE) -> 14 | S6: =VLOOKUP(C6,CU_ARS_2025_WOF_F2!$A$2:$K$673,6,FALSE) -> 1 | T6: =VLOOKUP(C6,CU_ARS_2025_WOF_F2!$A$2:$K$673,7,FALSE) -> 0 | U6: =VLOOKUP(C6,CU_ARS_2025_WOF_F2!$A$2:$K$673,8,FALSE) -> 1 | V6: =VLOOKUP(C6,CU_ARS_2025_WOF_F2!$A$2:$K$673,9,FALSE) -> 0 | W6: =VLOOKUP(C6,CU_ARS_2025_WOF_F2!$A$2:$K$673,10,FALSE) -> 0 | X6: =VLOOKUP(C6,CU_ARS_2025_WOF_F2!$A$2:$K$673,11,FALSE) -> 3 | Y6: NC20-4526
A7: Jannink | B7: USDA-Ithaca2025-O3K_01-07 | C7: 753636 | D7: 1 | E7: =O7 -> CU_ARS_2025_WOF_P_10_plant_2 | F7: F01 | G7: 6 | I7: AURORA | J7: P | N7: =VLOOKUP(C7,CU_ARS_2025_WOF_F2!$A$2:$K$673,2,FALSE) -> CU_ARS_2025_WOF_P_10_plant_2 | O7: =VLOOKUP(C7,CU_ARS_2025_WOF_F2!$A$2:$K$673,2,FALSE) -> CU_ARS_2025_WOF_P_10_plant_2 | P7: =VLOOKUP(C7,CU_ARS_2025_WOF_F2!$A$2:$K$673,3,FALSE) -> CU_ARS_2025_WOF_P_10 | Q7: =VLOOKUP(C7,CU_ARS_2025_WOF_F2!$A$2:$K$673,4,FALSE) -> AURORA | R7: =VLOOKUP(C7,CU_ARS_2025_WOF_F2!$A$2:$K$673,5,FALSE) -> 10 | S7: =VLOOKUP(C7,CU_ARS_2025_WOF_F2!$A$2:$K$673,6,FALSE) -> 1 | T7: =VLOOKUP(C7,CU_ARS_2025_WOF_F2!$A$2:$K$673,7,FALSE) -> 0 | U7: =VLOOKUP(C7,CU_ARS_2025_WOF_F2!$A$2:$K$673,8,FALSE) -> 1 | V7: =VLOOKUP(C7,CU_ARS_2025_WOF_F2!$A$2:$K$673,9,FALSE) -> 0 | W7: =VLOOKUP(C7,CU_ARS_2025_WOF_F2!$A$2:$K$673,10,FALSE) -> 0 | X7: =VLOOKUP(C7,CU_ARS_2025_WOF_F2!$A$2:$K$673,11,FALSE) -> 2 | Y7: AURORA
A8: Jannink | B8: USDA-Ithaca2025-O3K_01-07 | C8: 753856 | D8: 1 | E8: =O8 -> CU_ARS_2025_WOF_P_11_plant_2 | F8: G01 | G8: 7 | I8: AWNLESS_CURLED | J8: P | N8: =VLOOKUP(C8,CU_ARS_2025_WOF_F2!$A$2:$K$673,2,FALSE) -> CU_ARS_2025_WOF_P_11_plant_2 | O8: =VLOOKUP(C8,CU_ARS_2025_WOF_F2!$A$2:$K$673,2,FALSE) -> CU_ARS_2025_WOF_P_11_plant_2 | P8: =VLOOKUP(C8,CU_ARS_2025_WOF_F2!$A$2:$K$673,3,FALSE) -> CU_ARS_2025_WOF_P_11 | Q8: =VLOOKUP(C8,CU_ARS_2025_WOF_F2!$A$2:$K$673,4,FALSE) -> AWNLESS_CURLED | R8: =VLOOKUP(C8,CU_ARS_2025_WOF_F2!$A$2:$K$673,5,FALSE) -> 11 | S8: =VLOOKUP(C8,CU_ARS_2025_WOF_F2!$A$2:$K$673,6,FALSE) -> 1 | T8: =VLOOKUP(C8,CU_ARS_2025_WOF_F2!$A$2:$K$673,7,FALSE) -> 0 | U8: =VLOOKUP(C8,CU_ARS_2025_WOF_F2!$A$2:$K$673,8,FALSE) -> 1 | V8: =VLOOKUP(C8,CU_ARS_2025_WOF_F2!$A$2:$K$673,9,FALSE) -> 0 | W8: =VLOOKUP(C8,CU_ARS_2025_WOF_F2!$A$2:$K$673,10,FALSE) -> 0 | X8: =VLOOKUP(C8,CU_ARS_2025_WOF_F2!$A$2:$K$673,11,FALSE) -> 2 | Y8: AWNLESS_CURLED
A9: Jannink | B9: USDA-Ithaca2025-O3K_01-07 | C9: 754011 | D9: 1 | E9: =O9 -> CU_ARS_2025_WOF_P_12_plant_3 | F9: H01 | G9: 8 | I9: Gerard 227 | J9: P | N9: =VLOOKUP(C9,CU_ARS_2025_WOF_F2!$A$2:$K$673,2,FALSE) -> CU_ARS_2025_WOF_P_12_plant_3 | O9: =VLOOKUP(C9,CU_ARS_2025_WOF_F2!$A$2:$K$673,2,FALSE) -> CU_ARS_2025_WOF_P_12_plant_3 | P9: =VLOOKUP(C9,CU_ARS_2025_WOF_F2!$A$2:$K$673,3,FALSE) -> CU_ARS_2025_WOF_P_12 | Q9: =VLOOKUP(C9,CU_ARS_2025_WOF_F2!$A$2:$K$673,4,FALSE) -> Gerard 227 | R9: =VLOOKUP(C9,CU_ARS_2025_WOF_F2!$A$2:$K$673,5,FALSE) -> 12 | S9: =VLOOKUP(C9,CU_ARS_2025_WOF_F2!$A$2:$K$673,6,FALSE) -> 1 | T9: =VLOOKUP(C9,CU_ARS_2025_WOF_F2!$A$2:$K$673,7,FALSE) -> 0 | U9: =VLOOKUP(C9,CU_ARS_2025_WOF_F2!$A$2:$K$673,8,FALSE) -> 1 | V9: =VLOOKUP(C9,CU_ARS_2025_WOF_F2!$A$2:$K$673,9,FALSE) -> 0 | W9: =VLOOKUP(C9,CU_ARS_2025_WOF_F2!$A$2:$K$673,10,FALSE) -> 0 | X9: =VLOOKUP(C9,CU_ARS_2025_WOF_F2!$A$2:$K$673,11,FALSE) -> 3 | Y9: Gerard 227
A10: Jannink | B10: USDA-Ithaca2025-O3K_01-07 | C10: 754007 | D10: 1 | E10: =O10 -> CU_ARS_2025_WOF_P_13_plant_2 | F10: A02 | G10: 9 | I10: NC20-4452 | J10: P | N10: =VLOOKUP(C10,CU_ARS_2025_WOF_F2!$A$2:$K$673,2,FALSE) -> CU_ARS_2025_WOF_P_13_plant_2 | O10: =VLOOKUP(C10,CU_ARS_2025_WOF_F2!$A$2:$K$673,2,FALSE) -> CU_ARS_2025_WOF_P_13_plant_2 | P10: =VLOOKUP(C10,CU_ARS_2025_WOF_F2!$A$2:$K$673,3,FALSE) -> CU_ARS_2025_WOF_P_13 | Q10: =VLOOKUP(C10,CU_ARS_2025_WOF_F2!$A$2:$K$673,4,FALSE) -> NC20-4452 | R10: =VLOOKUP(C10,CU_ARS_2025_WOF_F2!$A$2:$K$673,5,FALSE) -> 13 | S10: =VLOOKUP(C10,CU_ARS_2025_WOF_F2!$A$2:$K$673,6,FALSE) -> 1 | T10: =VLOOKUP(C10,CU_ARS_2025_WOF_F2!$A$2:$K$673,7,FALSE) -> 0 | U10: =VLOOKUP(C10,CU_ARS_2025_WOF_F2!$A$2:$K$673,8,FALSE) -> 1 | V10: =VLOOKUP(C10,CU_ARS_2025_WOF_F2!$A$2:$K$673,9,FALSE) -> 0 | W10: =VLOOKUP(C10,CU_ARS_2025_WOF_F2!$A$2:$K$673,10,FALSE) -> 0 | X10: =VLOOKUP(C10,CU_ARS_2025_WOF_F2!$A$2:$K$673,11,FALSE) -> 2 | Y10: NC20-4452
A11: Jannink | B11: USDA-Ithaca2025-O3K_01-07 | C11: 754004 | D11: 1 | E11: =O11 -> CU_ARS_2025_WOF_P_14_plant_2 | F11: B02 | G11: 10 | I11: NC20-4526 | J11: P | N11: =VLOOKUP(C11,CU_ARS_2025_WOF_F2!$A$2:$K$673,2,FALSE) -> CU_ARS_2025_WOF_P_14_plant_2 | O11: =VLOOKUP(C11,CU_ARS_2025_WOF_F2!$A$2:$K$673,2,FALSE) -> CU_ARS_2025_WOF_P_14_plant_2 | P11: =VLOOKUP(C11,CU_ARS_2025_WOF_F2!$A$2:$K$673,3,FALSE) -> CU_ARS_2025_WOF_P_14 | Q11: =VLOOKUP(C11,CU_ARS_2025_WOF_F2!$A$2:$K$673,4,FALSE) -> NC20-4526 | R11: =VLOOKUP(C11,CU_ARS_2025_WOF_F2!$A$2:$K$673,5,FALSE) -> 14 | S11: =VLOOKUP(C11,CU_ARS_2025_WOF_F2!$A$2:$K$673,6,FALSE) -> 1 | T11: =VLOOKUP(C11,CU_ARS_2025_WOF_F2!$A$2:$K$673,7,FALSE) -> 0 | U11: =VLOOKUP(C11,CU_ARS_2025_WOF_F2!$A$2:$K$673,8,FALSE) -> 1 | V11: =VLOOKUP(C11,CU_ARS_2025_WOF_F2!$A$2:$K$673,9,FALSE) -> 0 | W11: =VLOOKUP(C11,CU_ARS_2025_WOF_F2!$A$2:$K$673,10,FALSE) -> 0 | X11: =VLOOKUP(C11,CU_ARS_2025_WOF_F2!$A$2:$K$673,11,FALSE) -> 2 | Y11: NC20-4526
A12: Jannink | B12: USDA-Ithaca2025-O3K_01-07 | C12: 753637 | D12: 1 | E12: =O12 -> CU_ARS_2025_WOF_P_10_plant_3 | F12: C02 | G12: 11 | I12: AURORA | J12: P | N12: =VLOOKUP(C12,CU_ARS_2025_WOF_F2!$A$2:$K$673,2,FALSE) -> CU_ARS_2025_WOF_P_10_plant_3 | O12: =VLOOKUP(C12,CU_ARS_2025_WOF_F2!$A$2:$K$673,2,FALSE) -> CU_ARS_2025_WOF_P_10_plant_3 | P12: =VLOOKUP(C12,CU_ARS_2025_WOF_F2!$A$2:$K$673,3,FALSE) -> CU_ARS_2025_WOF_P_10 | Q12: =VLOOKUP(C12,CU_ARS_2025_WOF_F2!$A$2:$K$673,4,FALSE) -> AURORA | R12: =VLOOKUP(C12,CU_ARS_2025_WOF_F2!$A$2:$K$673,5,FALSE) -> 10 | S12: =VLOOKUP(C12,CU_ARS_2025_WOF_F2!$A$2:$K$673,6,FALSE) -> 1 | T12: =VLOOKUP(C12,CU_ARS_2025_WOF_F2!$A$2:$K$673,7,FALSE) -> 0 | U12: =VLOOKUP(C12,CU_ARS_2025_WOF_F2!$A$2:$K$673,8,FALSE) -> 1 | V12: =VLOOKUP(C12,CU_ARS_2025_WOF_F2!$A$2:$K$673,9,FALSE) -> 0 | W12: =VLOOKUP(C12,CU_ARS_2025_WOF_F2!$A$2:$K$673,10,FALSE) -> 0 | X12: =VLOOKUP(C12,CU_ARS_2025_WOF_F2!$A$2:$K$673,11,FALSE) -> 3 | Y12: AURORA
A13: Jannink | B13: USDA-Ithaca2025-O3K_01-07 | C13: 753855 | D13: 1 | E13: =O13 -> CU_ARS_2025_WOF_P_11_plant_1 | F13: D02 | G13: 12 | I13: AWNLESS_CURLED | J13: P | N13: =VLOOKUP(C13,CU_ARS_2025_WOF_F2!$A$2:$K$673,2,FALSE) -> CU_ARS_2025_WOF_P_11_plant_1 | O13: =VLOOKUP(C13,CU_ARS_2025_WOF_F2!$A$2:$K$673,2,FALSE) -> CU_ARS_2025_WOF_P_11_plant_1 | P13: =VLOOKUP(C13,CU_ARS_2025_WOF_F2!$A$2:$K$673,3,FALSE) -> CU_ARS_2025_WOF_P_11 | Q13: =VLOOKUP(C13,CU_ARS_2025_WOF_F2!$A$2:$K$673,4,FALSE) -> AWNLESS_CURLED | R13: =VLOOKUP(C13,CU_ARS_2025_WOF_F2!$A$2:$K$673,5,FALSE) -> 11 | S13: =VLOOKUP(C13,CU_ARS_2025_WOF_F2!$A$2:$K$673,6,FALSE) -> 1 | T13: =VLOOKUP(C13,CU_ARS_2025_WOF_F2!$A$2:$K$673,7,FALSE) -> 0 | U13: =VLOOKUP(C13,CU_ARS_2025_WOF_F2!$A$2:$K$673,8,FALSE) -> 1 | V13: =VLOOKUP(C13,CU_ARS_2025_WOF_F2!$A$2:$K$673,9,FALSE) -> 0 | W13: =VLOOKUP(C13,CU_ARS_2025_WOF_F2!$A$2:$K$673,10,FALSE) -> 0 | X13: =VLOOKUP(C13,CU_ARS_2025_WOF_F2!$A$2:$K$673,11,FALSE) -> 1 | Y13: AWNLESS_CURLED
... A31: Jannink | B31: USDA-Ithaca2025-O3K_01-07 | C31: 753634 | D31: 1 | E31: =O31 -> CU_ARS_2025_WOF_P_18_plant_3 | F31: F04 | G31: 30 | I31: PA8014-840 | J31: P | N31: =VLOOKUP(C31,CU_ARS_2025_WOF_F2!$A$2:$K$673,2,FALSE) -> CU_ARS_2025_WOF_P_18_plant_3 | O31: =VLOOKUP(C31,CU_ARS_2025_WOF_F2!$A$2:$K$673,2,FALSE) -> CU_ARS_2025_WOF_P_18_plant_3 | P31: =VLOOKUP(C31,CU_ARS_2025_WOF_F2!$A$2:$K$673,3,FALSE) -> CU_ARS_2025_WOF_P_18 | Q31: =VLOOKUP(C31,CU_ARS_2025_WOF_F2!$A$2:$K$673,4,FALSE) -> PA8014-840 | R31: =VLOOKUP(C31,CU_ARS_2025_WOF_F2!$A$2:$K$673,5,FALSE) -> 18 | S31: =VLOOKUP(C31,CU_ARS_2025_WOF_F2!$A$2:$K$673,6,FALSE) -> 1 | T31: =VLOOKUP(C31,CU_ARS_2025_WOF_F2!$A$2:$K$673,7,FALSE) -> 0 | U31: =VLOOKUP(C31,CU_ARS_2025_WOF_F2!$A$2:$K$673,8,FALSE) -> 1 | V31: =VLOOKUP(C31,CU_ARS_2025_WOF_F2!$A$2:$K$673,9,FALSE) -> 0 | W31: =VLOOKUP(C31,CU_ARS_2025_WOF_F2!$A$2:$K$673,10,FALSE) -> 0 | X31: =VLOOKUP(C31,CU_ARS_2025_WOF_F2!$A$2:$K$673,11,FALSE) -> 3 | Y31: PA8014-840
A32: Jannink | B32: USDA-Ithaca2025-O3K_01-07 | C32: 753561 | D32: 1 | E32: =O32 -> CU_ARS_2025_WOF_F2_9_plant_1 | F32: G04 | G32: 31 | I32: AURORA/AWNLESS_CURLED | J32: F2 | N32: =VLOOKUP(C32,CU_ARS_2025_WOF_F2!$A$2:$K$673,2,FALSE) -> CU_ARS_2025_WOF_F2_9_plant_1 | O32: =VLOOKUP(C32,CU_ARS_2025_WOF_F2!$A$2:$K$673,2,FALSE) -> CU_ARS_2025_WOF_F2_9_plant_1 | P32: =VLOOKUP(C32,CU_ARS_2025_WOF_F2!$A$2:$K$673,3,FALSE) -> CU_ARS_2025_WOF_F2_9 | Q32: =VLOOKUP(C32,CU_ARS_2025_WOF_F2!$A$2:$K$673,4,FALSE) -> CU_ARS_2025_WOF_cross_1 | R32: =VLOOKUP(C32,CU_ARS_2025_WOF_F2!$A$2:$K$673,5,FALSE) -> 9 | S32: =VLOOKUP(C32,CU_ARS_2025_WOF_F2!$A$2:$K$673,6,FALSE) -> 1 | T32: =VLOOKUP(C32,CU_ARS_2025_WOF_F2!$A$2:$K$673,7,FALSE) -> 0 | U32: =VLOOKUP(C32,CU_ARS_2025_WOF_F2!$A$2:$K$673,8,FALSE) -> 1 | V32: =VLOOKUP(C32,CU_ARS_2025_WOF_F2!$A$2:$K$673,9,FALSE) -> 0 | W32: =VLOOKUP(C32,CU_ARS_2025_WOF_F2!$A$2:$K$673,10,FALSE) -> 0 | X32: =VLOOKUP(C32,CU_ARS_2025_WOF_F2!$A$2:$K$673,11,FALSE) -> 1 | Y32: =VLOOKUP(Q32,cross_pedigree!$A$2:$B$23,2,FALSE) -> AURORA/AWNLESS_CURLED
A33: Jannink | B33: USDA-Ithaca2025-O3K_01-07 | C33: 753562 | D33: 1 | E33: =O33 -> CU_ARS_2025_WOF_F2_9_plant_2 | F33: H04 | G33: 32 | I33: AURORA/AWNLESS_CURLED | J33: F2 | N33: =VLOOKUP(C33,CU_ARS_2025_WOF_F2!$A$2:$K$673,2,FALSE) -> CU_ARS_2025_WOF_F2_9_plant_2 | O33: =VLOOKUP(C33,CU_ARS_2025_WOF_F2!$A$2:$K$673,2,FALSE) -> CU_ARS_2025_WOF_F2_9_plant_2 | P33: =VLOOKUP(C33,CU_ARS_2025_WOF_F2!$A$2:$K$673,3,FALSE) -> CU_ARS_2025_WOF_F2_9 | Q33: =VLOOKUP(C33,CU_ARS_2025_WOF_F2!$A$2:$K$673,4,FALSE) -> CU_ARS_2025_WOF_cross_1 | R33: =VLOOKUP(C33,CU_ARS_2025_WOF_F2!$A$2:$K$673,5,FALSE) -> 9 | S33: =VLOOKUP(C33,CU_ARS_2025_WOF_F2!$A$2:$K$673,6,FALSE) -> 1 | T33: =VLOOKUP(C33,CU_ARS_2025_WOF_F2!$A$2:$K$673,7,FALSE) -> 0 | U33: =VLOOKUP(C33,CU_ARS_2025_WOF_F2!$A$2:$K$673,8,FALSE) -> 1 | V33: =VLOOKUP(C33,CU_ARS_2025_WOF_F2!$A$2:$K$673,9,FALSE) -> 0 | W33: =VLOOKUP(C33,CU_ARS_2025_WOF_F2!$A$2:$K$673,10,FALSE) -> 0 | X33: =VLOOKUP(C33,CU_ARS_2025_WOF_F2!$A$2:$K$673,11,FALSE) -> 2 | Y33: =VLOOKUP(Q33,cross_pedigree!$A$2:$B$23,2,FALSE) -> AURORA/AWNLESS_CURLED
A34: Jannink | B34: USDA-Ithaca2025-O3K_01-07 | C34: 753563 | D34: 1 | E34: =O34 -> CU_ARS_2025_WOF_F2_9_plant_3 | F34: A05 | G34: 33 | I34: AURORA/AWNLESS_CURLED | J34: F2 | N34: =VLOOKUP(C34,CU_ARS_2025_WOF_F2!$A$2:$K$673,2,FALSE) -> CU_ARS_2025_WOF_F2_9_plant_3 | O34: =VLOOKUP(C34,CU_ARS_2025_WOF_F2!$A$2:$K$673,2,FALSE) -> CU_ARS_2025_WOF_F2_9_plant_3 | P34: =VLOOKUP(C34,CU_ARS_2025_WOF_F2!$A$2:$K$673,3,FALSE) -> CU_ARS_2025_WOF_F2_9 | Q34: =VLOOKUP(C34,CU_ARS_2025_WOF_F2!$A$2:$K$673,4,FALSE) -> CU_ARS_2025_WOF_cross_1 | R34: =VLOOKUP(C34,CU_ARS_2025_WOF_F2!$A$2:$K$673,5,FALSE) -> 9 | S34: =VLOOKUP(C34,CU_ARS_2025_WOF_F2!$A$2:$K$673,6,FALSE) -> 1 | T34: =VLOOKUP(C34,CU_ARS_2025_WOF_F2!$A$2:$K$673,7,FALSE) -> 0 | U34: =VLOOKUP(C34,CU_ARS_2025_WOF_F2!$A$2:$K$673,8,FALSE) -> 1 | V34: =VLOOKUP(C34,CU_ARS_2025_WOF_F2!$A$2:$K$673,9,FALSE) -> 0 | W34: =VLOOKUP(C34,CU_ARS_2025_WOF_F2!$A$2:$K$673,10,FALSE) -> 0 | X34: =VLOOKUP(C34,CU_ARS_2025_WOF_F2!$A$2:$K$673,11,FALSE) -> 3 | Y34: =VLOOKUP(Q34,cross_pedigree!$A$2:$B$23,2,FALSE) -> AURORA/AWNLESS_CURLED
A35: Jannink | B35: USDA-Ithaca2025-O3K_01-07 | C35: 753564 | D35: 1 | E35: =O35 -> CU_ARS_2025_WOF_F2_9_plant_4 | F35: B05 | G35: 34 | I35: AURORA/AWNLESS_CURLED | J35: F2 | N35: =VLOOKUP(C35,CU_ARS_2025_WOF_F2!$A$2:$K$673,2,FALSE) -> CU_ARS_2025_WOF_F2_9_plant_4 | O35: =VLOOKUP(C35,CU_ARS_2025_WOF_F2!$A$2:$K$673,2,FALSE) -> CU_ARS_2025_WOF_F2_9_plant_4 | P35: =VLOOKUP(C35,CU_ARS_2025_WOF_F2!$A$2:$K$673,3,FALSE) -> CU_ARS_2025_WOF_F2_9 | Q35: =VLOOKUP(C35,CU_ARS_2025_WOF_F2!$A$2:$K$673,4,FALSE) -> CU_ARS_2025_WOF_cross_1 | R35: =VLOOKUP(C35,CU_ARS_2025_WOF_F2!$A$2:$K$673,5,FALSE) -> 9 | S35: =VLOOKUP(C35,CU_ARS_2025_WOF_F2!$A$2:$K$673,6,FALSE) -> 1 | T35: =VLOOKUP(C35,CU_ARS_2025_WOF_F2!$A$2:$K$673,7,FALSE) -> 0 | U35: =VLOOKUP(C35,CU_ARS_2025_WOF_F2!$A$2:$K$673,8,FALSE) -> 1 | V35: =VLOOKUP(C35,CU_ARS_2025_WOF_F2!$A$2:$K$673,9,FALSE) -> 0 | W35: =VLOOKUP(C35,CU_ARS_2025_WOF_F2!$A$2:$K$673,10,FALSE) -> 0 | X35: =VLOOKUP(C35,CU_ARS_2025_WOF_F2!$A$2:$K$673,11,FALSE) -> 4 | Y35: =VLOOKUP(Q35,cross_pedigree!$A$2:$B$23,2,FALSE) -> AURORA/AWNLESS_CURLED
A36: Jannink | B36: USDA-Ithaca2025-O3K_01-07 | C36: 753820 | D36: 1 | E36: =O36 -> CU_ARS_2025_WOF_F2_1_plant_41 | F36: C05 | G36: 35 | I36: PA8014-840/NC20-4452 | J36: F2 | N36: =VLOOKUP(C36,CU_ARS_2025_WOF_F2!$A$2:$K$673,2,FALSE) -> CU_ARS_2025_WOF_F2_1_plant_41 | O36: =VLOOKUP(C36,CU_ARS_2025_WOF_F2!$A$2:$K$673,2,FALSE) -> CU_ARS_2025_WOF_F2_1_plant_41 | P36: =VLOOKUP(C36,CU_ARS_2025_WOF_F2!$A$2:$K$673,3,FALSE) -> CU_ARS_2025_WOF_F2_1 | Q36: =VLOOKUP(C36,CU_ARS_2025_WOF_F2!$A$2:$K$673,4,FALSE) -> CU_ARS_2025_WOF_cross_55 | R36: =VLOOKUP(C36,CU_ARS_2025_WOF_F2!$A$2:$K$673,5,FALSE) -> 1 | S36: =VLOOKUP(C36,CU_ARS_2025_WOF_F2!$A$2:$K$673,6,FALSE) -> 1 | T36: =VLOOKUP(C36,CU_ARS_2025_WOF_F2!$A$2:$K$673,7,FALSE) -> 0 | U36: =VLOOKUP(C36,CU_ARS_2025_WOF_F2!$A$2:$K$673,8,FALSE) -> 1 | V36: =VLOOKUP(C36,CU_ARS_2025_WOF_F2!$A$2:$K$673,9,FALSE) -> 0 | W36: =VLOOKUP(C36,CU_ARS_2025_WOF_F2!$A$2:$K$673,10,FALSE) -> 0 | X36: =VLOOKUP(C36,CU_ARS_2025_WOF_F2!$A$2:$K$673,11,FALSE) -> 41 | Y36: =VLOOKUP(Q36,cross_pedigree!$A$2:$B$23,2,FALSE) -> PA8014-840/NC20-4452
A37: Jannink | B37: USDA-Ithaca2025-O3K_01-07 | C37: 753821 | D37: 1 | E37: =O37 -> CU_ARS_2025_WOF_F2_1_plant_42 | F37: D05 | G37: 36 | I37: PA8014-840/NC20-4452 | J37: F2 | N37: =VLOOKUP(C37,CU_ARS_2025_WOF_F2!$A$2:$K$673,2,FALSE) -> CU_ARS_2025_WOF_F2_1_plant_42 | O37: =VLOOKUP(C37,CU_ARS_2025_WOF_F2!$A$2:$K$673,2,FALSE) -> CU_ARS_2025_WOF_F2_1_plant_42 | P37: =VLOOKUP(C37,CU_ARS_2025_WOF_F2!$A$2:$K$673,3,FALSE) -> CU_ARS_2025_WOF_F2_1 | Q37: =VLOOKUP(C37,CU_ARS_2025_WOF_F2!$A$2:$K$673,4,FALSE) -> CU_ARS_2025_WOF_cross_55 | R37: =VLOOKUP(C37,CU_ARS_2025_WOF_F2!$A$2:$K$673,5,FALSE) -> 1 | S37: =VLOOKUP(C37,CU_ARS_2025_WOF_F2!$A$2:$K$673,6,FALSE) -> 1 | T37: =VLOOKUP(C37,CU_ARS_2025_WOF_F2!$A$2:$K$673,7,FALSE) -> 0 | U37: =VLOOKUP(C37,CU_ARS_2025_WOF_F2!$A$2:$K$673,8,FALSE) -> 1 | V37: =VLOOKUP(C37,CU_ARS_2025_WOF_F2!$A$2:$K$673,9,FALSE) -> 0 | W37: =VLOOKUP(C37,CU_ARS_2025_WOF_F2!$A$2:$K$673,10,FALSE) -> 0 | X37: =VLOOKUP(C37,CU_ARS_2025_WOF_F2!$A$2:$K$673,11,FALSE) -> 42 | Y37: =VLOOKUP(Q37,cross_pedigree!$A$2:$B$23,2,FALSE) -> PA8014-840/NC20-4452
A38: Jannink | B38: USDA-Ithaca2025-O3K_01-07 | C38: 753822 | D38: 1 | E38: =O38 -> CU_ARS_2025_WOF_F2_1_plant_43 | F38: E05 | G38: 37 | I38: PA8014-840/NC20-4452 | J38: F2 | N38: =VLOOKUP(C38,CU_ARS_2025_WOF_F2!$A$2:$K$673,2,FALSE) -> CU_ARS_2025_WOF_F2_1_plant_43 | O38: =VLOOKUP(C38,CU_ARS_2025_WOF_F2!$A$2:$K$673,2,FALSE) -> CU_ARS_2025_WOF_F2_1_plant_43 | P38: =VLOOKUP(C38,CU_ARS_2025_WOF_F2!$A$2:$K$673,3,FALSE) -> CU_ARS_2025_WOF_F2_1 | Q38: =VLOOKUP(C38,CU_ARS_2025_WOF_F2!$A$2:$K$673,4,FALSE) -> CU_ARS_2025_WOF_cross_55 | R38: =VLOOKUP(C38,CU_ARS_2025_WOF_F2!$A$2:$K$673,5,FALSE) -> 1 | S38: =VLOOKUP(C38,CU_ARS_2025_WOF_F2!$A$2:$K$673,6,FALSE) -> 1 | T38: =VLOOKUP(C38,CU_ARS_2025_WOF_F2!$A$2:$K$673,7,FALSE) -> 0 | U38: =VLOOKUP(C38,CU_ARS_2025_WOF_F2!$A$2:$K$673,8,FALSE) -> 1 | V38: =VLOOKUP(C38,CU_ARS_2025_WOF_F2!$A$2:$K$673,9,FALSE) -> 0 | W38: =VLOOKUP(C38,CU_ARS_2025_WOF_F2!$A$2:$K$673,10,FALSE) -> 0 | X38: =VLOOKUP(C38,CU_ARS_2025_WOF_F2!$A$2:$K$673,11,FALSE) -> 43 | Y38: =VLOOKUP(Q38,cross_pedigree!$A$2:$B$23,2,FALSE) -> PA8014-840/NC20-4452
A39: Jannink | B39: USDA-Ithaca2025-O3K_01-07 | C39: 753823 | D39: 1 | E39: =O39 -> CU_ARS_2025_WOF_F2_1_plant_44 | F39: F05 | G39: 38 | I39: PA8014-840/NC20-4452 | J39: F2 | N39: =VLOOKUP(C39,CU_ARS_2025_WOF_F2!$A$2:$K$673,2,FALSE) -> CU_ARS_2025_WOF_F2_1_plant_44 | O39: =VLOOKUP(C39,CU_ARS_2025_WOF_F2!$A$2:$K$673,2,FALSE) -> CU_ARS_2025_WOF_F2_1_plant_44 | P39: =VLOOKUP(C39,CU_ARS_2025_WOF_F2!$A$2:$K$673,3,FALSE) -> CU_ARS_2025_WOF_F2_1 | Q39: =VLOOKUP(C39,CU_ARS_2025_WOF_F2!$A$2:$K$673,4,FALSE) -> CU_ARS_2025_WOF_cross_55 | R39: =VLOOKUP(C39,CU_ARS_2025_WOF_F2!$A$2:$K$673,5,FALSE) -> 1 | S39: =VLOOKUP(C39,CU_ARS_2025_WOF_F2!$A$2:$K$673,6,FALSE) -> 1 | T39: =VLOOKUP(C39,CU_ARS_2025_WOF_F2!$A$2:$K$673,7,FALSE) -> 0 | U39: =VLOOKUP(C39,CU_ARS_2025_WOF_F2!$A$2:$K$673,8,FALSE) -> 1 | V39: =VLOOKUP(C39,CU_ARS_2025_WOF_F2!$A$2:$K$673,9,FALSE) -> 0 | W39: =VLOOKUP(C39,CU_ARS_2025_WOF_F2!$A$2:$K$673,10,FALSE) -> 0 | X39: =VLOOKUP(C39,CU_ARS_2025_WOF_F2!$A$2:$K$673,11,FALSE) -> 44 | Y39: =VLOOKUP(Q39,cross_pedigree!$A$2:$B$23,2,FALSE) -> PA8014-840/NC20-4452
A40: Jannink | B40: USDA-Ithaca2025-O3K_01-07 | C40: 753569 | D40: 1 | E40: =O40 -> CU_ARS_2025_WOF_F2_9_plant_9 | F40: G05 | G40: 39 | I40: AURORA/AWNLESS_CURLED | J40: F2 | N40: =VLOOKUP(C40,CU_ARS_2025_WOF_F2!$A$2:$K$673,2,FALSE) -> CU_ARS_2025_WOF_F2_9_plant_9 | O40: =VLOOKUP(C40,CU_ARS_2025_WOF_F2!$A$2:$K$673,2,FALSE) -> CU_ARS_2025_WOF_F2_9_plant_9 | P40: =VLOOKUP(C40,CU_ARS_2025_WOF_F2!$A$2:$K$673,3,FALSE) -> CU_ARS_2025_WOF_F2_9 | Q40: =VLOOKUP(C40,CU_ARS_2025_WOF_F2!$A$2:$K$673,4,FALSE) -> CU_ARS_2025_WOF_cross_1 | R40: =VLOOKUP(C40,CU_ARS_2025_WOF_F2!$A$2:$K$673,5,FALSE) -> 9 | S40: =VLOOKUP(C40,CU_ARS_2025_WOF_F2!$A$2:$K$673,6,FALSE) -> 1 | T40: =VLOOKUP(C40,CU_ARS_2025_WOF_F2!$A$2:$K$673,7,FALSE) -> 0 | U40: =VLOOKUP(C40,CU_ARS_2025_WOF_F2!$A$2:$K$673,8,FALSE) -> 1 | V40: =VLOOKUP(C40,CU_ARS_2025_WOF_F2!$A$2:$K$673,9,FALSE) -> 0 | W40: =VLOOKUP(C40,CU_ARS_2025_WOF_F2!$A$2:$K$673,10,FALSE) -> 0 | X40: =VLOOKUP(C40,CU_ARS_2025_WOF_F2!$A$2:$K$673,11,FALSE) -> 9 | Y40: =VLOOKUP(Q40,cross_pedigree!$A$2:$B$23,2,FALSE) -> AURORA/AWNLESS_CURLED
A41: Jannink | B41: USDA-Ithaca2025-O3K_01-07 | C41: 753570 | D41: 1 | E41: =O41 -> CU_ARS_2025_WOF_F2_9_plant_10 | F41: H05 | G41: 40 | I41: AURORA/AWNLESS_CURLED | J41: F2 | N41: =VLOOKUP(C41,CU_ARS_2025_WOF_F2!$A$2:$K$673,2,FALSE) -> CU_ARS_2025_WOF_F2_9_plant_10 | O41: =VLOOKUP(C41,CU_ARS_2025_WOF_F2!$A$2:$K$673,2,FALSE) -> CU_ARS_2025_WOF_F2_9_plant_10 | P41: =VLOOKUP(C41,CU_ARS_2025_WOF_F2!$A$2:$K$673,3,FALSE) -> CU_ARS_2025_WOF_F2_9 | Q41: =VLOOKUP(C41,CU_ARS_2025_WOF_F2!$A$2:$K$673,4,FALSE) -> CU_ARS_2025_WOF_cross_1 | R41: =VLOOKUP(C41,CU_ARS_2025_WOF_F2!$A$2:$K$673,5,FALSE) -> 9 | S41: =VLOOKUP(C41,CU_ARS_2025_WOF_F2!$A$2:$K$673,6,FALSE) -> 1 | T41: =VLOOKUP(C41,CU_ARS_2025_WOF_F2!$A$2:$K$673,7,FALSE) -> 0 | U41: =VLOOKUP(C41,CU_ARS_2025_WOF_F2!$A$2:$K$673,8,FALSE) -> 1 | V41: =VLOOKUP(C41,CU_ARS_2025_WOF_F2!$A$2:$K$673,9,FALSE) -> 0 | W41: =VLOOKUP(C41,CU_ARS_2025_WOF_F2!$A$2:$K$673,10,FALSE) -> 0 | X41: =VLOOKUP(C41,CU_ARS_2025_WOF_F2!$A$2:$K$673,11,FALSE) -> 10 | Y41: =VLOOKUP(Q41,cross_pedigree!$A$2:$B$23,2,FALSE) -> AURORA/AWNLESS_CURLED
A42: Jannink | B42: USDA-Ithaca2025-O3K_01-07 | C42: 753571 | D42: 1 | E42: =O42 -> CU_ARS_2025_WOF_F2_9_plant_11 | F42: A06 | G42: 41 | I42: AURORA/AWNLESS_CURLED | J42: F2 | N42: =VLOOKUP(C42,CU_ARS_2025_WOF_F2!$A$2:$K$673,2,FALSE) -> CU_ARS_2025_WOF_F2_9_plant_11 | O42: =VLOOKUP(C42,CU_ARS_2025_WOF_F2!$A$2:$K$673,2,FALSE) -> CU_ARS_2025_WOF_F2_9_plant_11 | P42: =VLOOKUP(C42,CU_ARS_2025_WOF_F2!$A$2:$K$673,3,FALSE) -> CU_ARS_2025_WOF_F2_9 | Q42: =VLOOKUP(C42,CU_ARS_2025_WOF_F2!$A$2:$K$673,4,FALSE) -> CU_ARS_2025_WOF_cross_1 | R42: =VLOOKUP(C42,CU_ARS_2025_WOF_F2!$A$2:$K$673,5,FALSE) -> 9 | S42: =VLOOKUP(C42,CU_ARS_2025_WOF_F2!$A$2:$K$673,6,FALSE) -> 1 | T42: =VLOOKUP(C42,CU_ARS_2025_WOF_F2!$A$2:$K$673,7,FALSE) -> 0 | U42: =VLOOKUP(C42,CU_ARS_2025_WOF_F2!$A$2:$K$673,8,FALSE) -> 1 | V42: =VLOOKUP(C42,CU_ARS_2025_WOF_F2!$A$2:$K$673,9,FALSE) -> 0 | W42: =VLOOKUP(C42,CU_ARS_2025_WOF_F2!$A$2:$K$673,10,FALSE) -> 0 | X42: =VLOOKUP(C42,CU_ARS_2025_WOF_F2!$A$2:$K$673,11,FALSE) -> 11 | Y42: =VLOOKUP(Q42,cross_pedigree!$A$2:$B$23,2,FALSE) -> AURORA/AWNLESS_CURLED
A43: Jannink | B43: USDA-Ithaca2025-O3K_01-07 | C43: 753572 | D43: 1 | E43: =O43 -> CU_ARS_2025_WOF_F2_9_plant_12 | F43: B06 | G43: 42 | I43: AURORA/AWNLESS_CURLED | J43: F2 | N43: =VLOOKUP(C43,CU_ARS_2025_WOF_F2!$A$2:$K$673,2,FALSE) -> CU_ARS_2025_WOF_F2_9_plant_12 | O43: =VLOOKUP(C43,CU_ARS_2025_WOF_F2!$A$2:$K$673,2,FALSE) -> CU_ARS_2025_WOF_F2_9_plant_12 | P43: =VLOOKUP(C43,CU_ARS_2025_WOF_F2!$A$2:$K$673,3,FALSE) -> CU_ARS_2025_WOF_F2_9 | Q43: =VLOOKUP(C43,CU_ARS_2025_WOF_F2!$A$2:$K$673,4,FALSE) -> CU_ARS_2025_WOF_cross_1 | R43: =VLOOKUP(C43,CU_ARS_2025_WOF_F2!$A$2:$K$673,5,FALSE) -> 9 | S43: =VLOOKUP(C43,CU_ARS_2025_WOF_F2!$A$2:$K$673,6,FALSE) -> 1 | T43: =VLOOKUP(C43,CU_ARS_2025_WOF_F2!$A$2:$K$673,7,FALSE) -> 0 | U43: =VLOOKUP(C43,CU_ARS_2025_WOF_F2!$A$2:$K$673,8,FALSE) -> 1 | V43: =VLOOKUP(C43,CU_ARS_2025_WOF_F2!$A$2:$K$673,9,FALSE) -> 0 | W43: =VLOOKUP(C43,CU_ARS_2025_WOF_F2!$A$2:$K$673,10,FALSE) -> 0 | X43: =VLOOKUP(C43,CU_ARS_2025_WOF_F2!$A$2:$K$673,11,FALSE) -> 12 | Y43: =VLOOKUP(Q43,cross_pedigree!$A$2:$B$23,2,FALSE) -> AURORA/AWNLESS_CURLED
... A394: Jannink | B394: USDA-Ithaca2025-O3K_01-07 | C394: 754073 | D394: 5 | E394: =O394 -> CU_ARS_2025_WOF_F2_3_plant_59 | F394: A02 | G394: 09 | I394: Gerard 227/PA8014-840 | J394: F2 | N394: =VLOOKUP(C394,CU_ARS_2025_WOF_F2!$A$2:$K$673,2,FALSE) -> CU_ARS_2025_WOF_F2_3_plant_59 | O394: =VLOOKUP(C394,CU_ARS_2025_WOF_F2!$A$2:$K$673,2,FALSE) -> CU_ARS_2025_WOF_F2_3_plant_59 | P394: =VLOOKUP(C394,CU_ARS_2025_WOF_F2!$A$2:$K$673,3,FALSE) -> CU_ARS_2025_WOF_F2_3 | Q394: =VLOOKUP(C394,CU_ARS_2025_WOF_F2!$A$2:$K$673,4,FALSE) -> CU_ARS_2025_WOF_cross_87 | R394: =VLOOKUP(C394,CU_ARS_2025_WOF_F2!$A$2:$K$673,5,FALSE) -> 3 | S394: =VLOOKUP(C394,CU_ARS_2025_WOF_F2!$A$2:$K$673,6,FALSE) -> 1 | T394: =VLOOKUP(C394,CU_ARS_2025_WOF_F2!$A$2:$K$673,7,FALSE) -> 0 | U394: =VLOOKUP(C394,CU_ARS_2025_WOF_F2!$A$2:$K$673,8,FALSE) -> 1 | V394: =VLOOKUP(C394,CU_ARS_2025_WOF_F2!$A$2:$K$673,9,FALSE) -> 0 | W394: =VLOOKUP(C394,CU_ARS_2025_WOF_F2!$A$2:$K$673,10,FALSE) -> 0 | X394: =VLOOKUP(C394,CU_ARS_2025_WOF_F2!$A$2:$K$673,11,FALSE) -> 59 | Y394: =VLOOKUP(Q394,cross_pedigree!$A$2:$B$23,2,FALSE) -> Gerard 227/PA8014-840
A395: Jannink | B395: USDA-Ithaca2025-O3K_01-07 | C395: 754074 | D395: 5 | E395: =O395 -> CU_ARS_2025_WOF_F2_3_plant_60 | F395: B02 | G395: 10 | I395: Gerard 227/PA8014-840 | J395: F2 | N395: =VLOOKUP(C395,CU_ARS_2025_WOF_F2!$A$2:$K$673,2,FALSE) -> CU_ARS_2025_WOF_F2_3_plant_60 | O395: =VLOOKUP(C395,CU_ARS_2025_WOF_F2!$A$2:$K$673,2,FALSE) -> CU_ARS_2025_WOF_F2_3_plant_60 | P395: =VLOOKUP(C395,CU_ARS_2025_WOF_F2!$A$2:$K$673,3,FALSE) -> CU_ARS_2025_WOF_F2_3 | Q395: =VLOOKUP(C395,CU_ARS_2025_WOF_F2!$A$2:$K$673,4,FALSE) -> CU_ARS_2025_WOF_cross_87 | R395: =VLOOKUP(C395,CU_ARS_2025_WOF_F2!$A$2:$K$673,5,FALSE) -> 3 | S395: =VLOOKUP(C395,CU_ARS_2025_WOF_F2!$A$2:$K$673,6,FALSE) -> 1 | T395: =VLOOKUP(C395,CU_ARS_2025_WOF_F2!$A$2:$K$673,7,FALSE) -> 0 | U395: =VLOOKUP(C395,CU_ARS_2025_WOF_F2!$A$2:$K$673,8,FALSE) -> 1 | V395: =VLOOKUP(C395,CU_ARS_2025_WOF_F2!$A$2:$K$673,9,FALSE) -> 0 | W395: =VLOOKUP(C395,CU_ARS_2025_WOF_F2!$A$2:$K$673,10,FALSE) -> 0 | X395: =VLOOKUP(C395,CU_ARS_2025_WOF_F2!$A$2:$K$673,11,FALSE) -> 60 | Y395: =VLOOKUP(Q395,cross_pedigree!$A$2:$B$23,2,FALSE) -> Gerard 227/PA8014-840
A396: Jannink | B396: USDA-Ithaca2025-O3K_01-07 | C396: 754075 | D396: 5 | E396: =O396 -> CU_ARS_2025_WOF_F2_3_plant_61 | F396: C02 | G396: 11 | I396: Gerard 227/PA8014-840 | J396: F2 | N396: =VLOOKUP(C396,CU_ARS_2025_WOF_F2!$A$2:$K$673,2,FALSE) -> CU_ARS_2025_WOF_F2_3_plant_61 | O396: =VLOOKUP(C396,CU_ARS_2025_WOF_F2!$A$2:$K$673,2,FALSE) -> CU_ARS_2025_WOF_F2_3_plant_61 | P396: =VLOOKUP(C396,CU_ARS_2025_WOF_F2!$A$2:$K$673,3,FALSE) -> CU_ARS_2025_WOF_F2_3 | Q396: =VLOOKUP(C396,CU_ARS_2025_WOF_F2!$A$2:$K$673,4,FALSE) -> CU_ARS_2025_WOF_cross_87 | R396: =VLOOKUP(C396,CU_ARS_2025_WOF_F2!$A$2:$K$673,5,FALSE) -> 3 | S396: =VLOOKUP(C396,CU_ARS_2025_WOF_F2!$A$2:$K$673,6,FALSE) -> 1 | T396: =VLOOKUP(C396,CU_ARS_2025_WOF_F2!$A$2:$K$673,7,FALSE) -> 0 | U396: =VLOOKUP(C396,CU_ARS_2025_WOF_F2!$A$2:$K$673,8,FALSE) -> 1 | V396: =VLOOKUP(C396,CU_ARS_2025_WOF_F2!$A$2:$K$673,9,FALSE) -> 0 | W396: =VLOOKUP(C396,CU_ARS_2025_WOF_F2!$A$2:$K$673,10,FALSE) -> 0 | X396: =VLOOKUP(C396,CU_ARS_2025_WOF_F2!$A$2:$K$673,11,FALSE) -> 61 | Y396: =VLOOKUP(Q396,cross_pedigree!$A$2:$B$23,2,FALSE) -> Gerard 227/PA8014-840
A397: Jannink | B397: USDA-Ithaca2025-O3K_01-07 | C397: 753998 | D397: 5 | E397: =O397 -> CU_ARS_2025_WOF_F2_5_plant_67 | F397: D02 | G397: 12 | I397: Gerard 227/NF13-4126-4_3 | J397: F2 | N397: =VLOOKUP(C397,CU_ARS_2025_WOF_F2!$A$2:$K$673,2,FALSE) -> CU_ARS_2025_WOF_F2_5_plant_67 | O397: =VLOOKUP(C397,CU_ARS_2025_WOF_F2!$A$2:$K$673,2,FALSE) -> CU_ARS_2025_WOF_F2_5_plant_67 | P397: =VLOOKUP(C397,CU_ARS_2025_WOF_F2!$A$2:$K$673,3,FALSE) -> CU_ARS_2025_WOF_F2_5 | Q397: =VLOOKUP(C397,CU_ARS_2025_WOF_F2!$A$2:$K$673,4,FALSE) -> CU_ARS_2025_WOF_cross_54 | R397: =VLOOKUP(C397,CU_ARS_2025_WOF_F2!$A$2:$K$673,5,FALSE) -> 5 | S397: =VLOOKUP(C397,CU_ARS_2025_WOF_F2!$A$2:$K$673,6,FALSE) -> 1 | T397: =VLOOKUP(C397,CU_ARS_2025_WOF_F2!$A$2:$K$673,7,FALSE) -> 0 | U397: =VLOOKUP(C397,CU_ARS_2025_WOF_F2!$A$2:$K$673,8,FALSE) -> 1 | V397: =VLOOKUP(C397,CU_ARS_2025_WOF_F2!$A$2:$K$673,9,FALSE) -> 0 | W397: =VLOOKUP(C397,CU_ARS_2025_WOF_F2!$A$2:$K$673,10,FALSE) -> 0 | X397: =VLOOKUP(C397,CU_ARS_2025_WOF_F2!$A$2:$K$673,11,FALSE) -> 67 | Y397: =VLOOKUP(Q397,cross_pedigree!$A$2:$B$23,2,FALSE) -> Gerard 227/NF13-4126-4_3
A398: Jannink | B398: USDA-Ithaca2025-O3K_01-07 | C398: 753987 | D398: 5 | E398: =O398 -> CU_ARS_2025_WOF_F2_5_plant_56 | F398: E02 | G398: 13 | I398: Gerard 227/NF13-4126-4_3 | J398: F2 | N398: =VLOOKUP(C398,CU_ARS_2025_WOF_F2!$A$2:$K$673,2,FALSE) -> CU_ARS_2025_WOF_F2_5_plant_56 | O398: =VLOOKUP(C398,CU_ARS_2025_WOF_F2!$A$2:$K$673,2,FALSE) -> CU_ARS_2025_WOF_F2_5_plant_56 | P398: =VLOOKUP(C398,CU_ARS_2025_WOF_F2!$A$2:$K$673,3,FALSE) -> CU_ARS_2025_WOF_F2_5 | Q398: =VLOOKUP(C398,CU_ARS_2025_WOF_F2!$A$2:$K$673,4,FALSE) -> CU_ARS_2025_WOF_cross_54 | R398: =VLOOKUP(C398,CU_ARS_2025_WOF_F2!$A$2:$K$673,5,FALSE) -> 5 | S398: =VLOOKUP(C398,CU_ARS_2025_WOF_F2!$A$2:$K$673,6,FALSE) -> 1 | T398: =VLOOKUP(C398,CU_ARS_2025_WOF_F2!$A$2:$K$673,7,FALSE) -> 0 | U398: =VLOOKUP(C398,CU_ARS_2025_WOF_F2!$A$2:$K$673,8,FALSE) -> 1 | V398: =VLOOKUP(C398,CU_ARS_2025_WOF_F2!$A$2:$K$673,9,FALSE) -> 0 | W398: =VLOOKUP(C398,CU_ARS_2025_WOF_F2!$A$2:$K$673,10,FALSE) -> 0 | X398: =VLOOKUP(C398,CU_ARS_2025_WOF_F2!$A$2:$K$673,11,FALSE) -> 56 | Y398: =VLOOKUP(Q398,cross_pedigree!$A$2:$B$23,2,FALSE) -> Gerard 227/NF13-4126-4_3
A399: Jannink | B399: USDA-Ithaca2025-O3K_01-07 | C399: 753988 | D399: 5 | E399: =O399 -> CU_ARS_2025_WOF_F2_5_plant_57 | F399: F02 | G399: 14 | I399: Gerard 227/NF13-4126-4_3 | J399: F2 | N399: =VLOOKUP(C399,CU_ARS_2025_WOF_F2!$A$2:$K$673,2,FALSE) -> CU_ARS_2025_WOF_F2_5_plant_57 | O399: =VLOOKUP(C399,CU_ARS_2025_WOF_F2!$A$2:$K$673,2,FALSE) -> CU_ARS_2025_WOF_F2_5_plant_57 | P399: =VLOOKUP(C399,CU_ARS_2025_WOF_F2!$A$2:$K$673,3,FALSE) -> CU_ARS_2025_WOF_F2_5 | Q399: =VLOOKUP(C399,CU_ARS_2025_WOF_F2!$A$2:$K$673,4,FALSE) -> CU_ARS_2025_WOF_cross_54 | R399: =VLOOKUP(C399,CU_ARS_2025_WOF_F2!$A$2:$K$673,5,FALSE) -> 5 | S399: =VLOOKUP(C399,CU_ARS_2025_WOF_F2!$A$2:$K$673,6,FALSE) -> 1 | T399: =VLOOKUP(C399,CU_ARS_2025_WOF_F2!$A$2:$K$673,7,FALSE) -> 0 | U399: =VLOOKUP(C399,CU_ARS_2025_WOF_F2!$A$2:$K$673,8,FALSE) -> 1 | V399: =VLOOKUP(C399,CU_ARS_2025_WOF_F2!$A$2:$K$673,9,FALSE) -> 0 | W399: =VLOOKUP(C399,CU_ARS_2025_WOF_F2!$A$2:$K$673,10,FALSE) -> 0 | X399: =VLOOKUP(C399,CU_ARS_2025_WOF_F2!$A$2:$K$673,11,FALSE) -> 57 | Y399: =VLOOKUP(Q399,cross_pedigree!$A$2:$B$23,2,FALSE) -> Gerard 227/NF13-4126-4_3
A400: Jannink | B400: USDA-Ithaca2025-O3K_01-07 | C400: 754027 | D400: 5 | E400: =O400 -> CU_ARS_2025_WOF_F2_3_plant_13 | F400: G02 | G400: 15 | I400: Gerard 227/PA8014-840 | J400: F2 | N400: =VLOOKUP(C400,CU_ARS_2025_WOF_F2!$A$2:$K$673,2,FALSE) -> CU_ARS_2025_WOF_F2_3_plant_13 | O400: =VLOOKUP(C400,CU_ARS_2025_WOF_F2!$A$2:$K$673,2,FALSE) -> CU_ARS_2025_WOF_F2_3_plant_13 | P400: =VLOOKUP(C400,CU_ARS_2025_WOF_F2!$A$2:$K$673,3,FALSE) -> CU_ARS_2025_WOF_F2_3 | Q400: =VLOOKUP(C400,CU_ARS_2025_WOF_F2!$A$2:$K$673,4,FALSE) -> CU_ARS_2025_WOF_cross_87 | R400: =VLOOKUP(C400,CU_ARS_2025_WOF_F2!$A$2:$K$673,5,FALSE) -> 3 | S400: =VLOOKUP(C400,CU_ARS_2025_WOF_F2!$A$2:$K$673,6,FALSE) -> 1 | T400: =VLOOKUP(C400,CU_ARS_2025_WOF_F2!$A$2:$K$673,7,FALSE) -> 0 | U400: =VLOOKUP(C400,CU_ARS_2025_WOF_F2!$A$2:$K$673,8,FALSE) -> 1 | V400: =VLOOKUP(C400,CU_ARS_2025_WOF_F2!$A$2:$K$673,9,FALSE) -> 0 | W400: =VLOOKUP(C400,CU_ARS_2025_WOF_F2!$A$2:$K$673,10,FALSE) -> 0 | X400: =VLOOKUP(C400,CU_ARS_2025_WOF_F2!$A$2:$K$673,11,FALSE) -> 13 | Y400: =VLOOKUP(Q400,cross_pedigree!$A$2:$B$23,2,FALSE) -> Gerard 227/PA8014-840
A401: Jannink | B401: USDA-Ithaca2025-O3K_01-07 | C401: 754026 | D401: 5 | E401: =O401 -> CU_ARS_2025_WOF_F2_3_plant_12 | F401: H02 | G401: 16 | I401: Gerard 227/PA8014-840 | J401: F2 | N401: =VLOOKUP(C401,CU_ARS_2025_WOF_F2!$A$2:$K$673,2,FALSE) -> CU_ARS_2025_WOF_F2_3_plant_12 | O401: =VLOOKUP(C401,CU_ARS_2025_WOF_F2!$A$2:$K$673,2,FALSE) -> CU_ARS_2025_WOF_F2_3_plant_12 | P401: =VLOOKUP(C401,CU_ARS_2025_WOF_F2!$A$2:$K$673,3,FALSE) -> CU_ARS_2025_WOF_F2_3 | Q401: =VLOOKUP(C401,CU_ARS_2025_WOF_F2!$A$2:$K$673,4,FALSE) -> CU_ARS_2025_WOF_cross_87 | R401: =VLOOKUP(C401,CU_ARS_2025_WOF_F2!$A$2:$K$673,5,FALSE) -> 3 | S401: =VLOOKUP(C401,CU_ARS_2025_WOF_F2!$A$2:$K$673,6,FALSE) -> 1 | T401: =VLOOKUP(C401,CU_ARS_2025_WOF_F2!$A$2:$K$673,7,FALSE) -> 0 | U401: =VLOOKUP(C401,CU_ARS_2025_WOF_F2!$A$2:$K$673,8,FALSE) -> 1 | V401: =VLOOKUP(C401,CU_ARS_2025_WOF_F2!$A$2:$K$673,9,FALSE) -> 0 | W401: =VLOOKUP(C401,CU_ARS_2025_WOF_F2!$A$2:$K$673,10,FALSE) -> 0 | X401: =VLOOKUP(C401,CU_ARS_2025_WOF_F2!$A$2:$K$673,11,FALSE) -> 12 | Y401: =VLOOKUP(Q401,cross_pedigree!$A$2:$B$23,2,FALSE) -> Gerard 227/PA8014-840
A402: Jannink | B402: USDA-Ithaca2025-O3K_01-07 | C402: 754025 | D402: 5 | E402: =O402 -> CU_ARS_2025_WOF_F2_3_plant_11 | F402: A03 | G402: 17 | I402: Gerard 227/PA8014-840 | J402: F2 | N402: =VLOOKUP(C402,CU_ARS_2025_WOF_F2!$A$2:$K$673,2,FALSE) -> CU_ARS_2025_WOF_F2_3_plant_11 | O402: =VLOOKUP(C402,CU_ARS_2025_WOF_F2!$A$2:$K$673,2,FALSE) -> CU_ARS_2025_WOF_F2_3_plant_11 | P402: =VLOOKUP(C402,CU_ARS_2025_WOF_F2!$A$2:$K$673,3,FALSE) -> CU_ARS_2025_WOF_F2_3 | Q402: =VLOOKUP(C402,CU_ARS_2025_WOF_F2!$A$2:$K$673,4,FALSE) -> CU_ARS_2025_WOF_cross_87 | R402: =VLOOKUP(C402,CU_ARS_2025_WOF_F2!$A$2:$K$673,5,FALSE) -> 3 | S402: =VLOOKUP(C402,CU_ARS_2025_WOF_F2!$A$2:$K$673,6,FALSE) -> 1 | T402: =VLOOKUP(C402,CU_ARS_2025_WOF_F2!$A$2:$K$673,7,FALSE) -> 0 | U402: =VLOOKUP(C402,CU_ARS_2025_WOF_F2!$A$2:$K$673,8,FALSE) -> 1 | V402: =VLOOKUP(C402,CU_ARS_2025_WOF_F2!$A$2:$K$673,9,FALSE) -> 0 | W402: =VLOOKUP(C402,CU_ARS_2025_WOF_F2!$A$2:$K$673,10,FALSE) -> 0 | X402: =VLOOKUP(C402,CU_ARS_2025_WOF_F2!$A$2:$K$673,11,FALSE) -> 11 | Y402: =VLOOKUP(Q402,cross_pedigree!$A$2:$B$23,2,FALSE) -> Gerard 227/PA8014-840
A403: Jannink | B403: USDA-Ithaca2025-O3K_01-07 | C403: 754020 | D403: 5 | E403: =O403 -> CU_ARS_2025_WOF_F2_3_plant_6 | F403: B03 | G403: 18 | I403: Gerard 227/PA8014-840 | J403: F2 | N403: =VLOOKUP(C403,CU_ARS_2025_WOF_F2!$A$2:$K$673,2,FALSE) -> CU_ARS_2025_WOF_F2_3_plant_6 | O403: =VLOOKUP(C403,CU_ARS_2025_WOF_F2!$A$2:$K$673,2,FALSE) -> CU_ARS_2025_WOF_F2_3_plant_6 | P403: =VLOOKUP(C403,CU_ARS_2025_WOF_F2!$A$2:$K$673,3,FALSE) -> CU_ARS_2025_WOF_F2_3 | Q403: =VLOOKUP(C403,CU_ARS_2025_WOF_F2!$A$2:$K$673,4,FALSE) -> CU_ARS_2025_WOF_cross_87 | R403: =VLOOKUP(C403,CU_ARS_2025_WOF_F2!$A$2:$K$673,5,FALSE) -> 3 | S403: =VLOOKUP(C403,CU_ARS_2025_WOF_F2!$A$2:$K$673,6,FALSE) -> 1 | T403: =VLOOKUP(C403,CU_ARS_2025_WOF_F2!$A$2:$K$673,7,FALSE) -> 0 | U403: =VLOOKUP(C403,CU_ARS_2025_WOF_F2!$A$2:$K$673,8,FALSE) -> 1 | V403: =VLOOKUP(C403,CU_ARS_2025_WOF_F2!$A$2:$K$673,9,FALSE) -> 0 | W403: =VLOOKUP(C403,CU_ARS_2025_WOF_F2!$A$2:$K$673,10,FALSE) -> 0 | X403: =VLOOKUP(C403,CU_ARS_2025_WOF_F2!$A$2:$K$673,11,FALSE) -> 6 | Y403: =VLOOKUP(Q403,cross_pedigree!$A$2:$B$23,2,FALSE) -> Gerard 227/PA8014-840
A404: Jannink | B404: USDA-Ithaca2025-O3K_01-07 | C404: 754021 | D404: 5 | E404: =O404 -> CU_ARS_2025_WOF_F2_3_plant_7 | F404: C03 | G404: 19 | I404: Gerard 227/PA8014-840 | J404: F2 | N404: =VLOOKUP(C404,CU_ARS_2025_WOF_F2!$A$2:$K$673,2,FALSE) -> CU_ARS_2025_WOF_F2_3_plant_7 | O404: =VLOOKUP(C404,CU_ARS_2025_WOF_F2!$A$2:$K$673,2,FALSE) -> CU_ARS_2025_WOF_F2_3_plant_7 | P404: =VLOOKUP(C404,CU_ARS_2025_WOF_F2!$A$2:$K$673,3,FALSE) -> CU_ARS_2025_WOF_F2_3 | Q404: =VLOOKUP(C404,CU_ARS_2025_WOF_F2!$A$2:$K$673,4,FALSE) -> CU_ARS_2025_WOF_cross_87 | R404: =VLOOKUP(C404,CU_ARS_2025_WOF_F2!$A$2:$K$673,5,FALSE) -> 3 | S404: =VLOOKUP(C404,CU_ARS_2025_WOF_F2!$A$2:$K$673,6,FALSE) -> 1 | T404: =VLOOKUP(C404,CU_ARS_2025_WOF_F2!$A$2:$K$673,7,FALSE) -> 0 | U404: =VLOOKUP(C404,CU_ARS_2025_WOF_F2!$A$2:$K$673,8,FALSE) -> 1 | V404: =VLOOKUP(C404,CU_ARS_2025_WOF_F2!$A$2:$K$673,9,FALSE) -> 0 | W404: =VLOOKUP(C404,CU_ARS_2025_WOF_F2!$A$2:$K$673,10,FALSE) -> 0 | X404: =VLOOKUP(C404,CU_ARS_2025_WOF_F2!$A$2:$K$673,11,FALSE) -> 7 | Y404: =VLOOKUP(Q404,cross_pedigree!$A$2:$B$23,2,FALSE) -> Gerard 227/PA8014-840
A405: Jannink | B405: USDA-Ithaca2025-O3K_01-07 | C405: 753991 | D405: 5 | E405: =O405 -> CU_ARS_2025_WOF_F2_5_plant_60 | F405: D03 | G405: 20 | I405: Gerard 227/NF13-4126-4_3 | J405: F2 | N405: =VLOOKUP(C405,CU_ARS_2025_WOF_F2!$A$2:$K$673,2,FALSE) -> CU_ARS_2025_WOF_F2_5_plant_60 | O405: =VLOOKUP(C405,CU_ARS_2025_WOF_F2!$A$2:$K$673,2,FALSE) -> CU_ARS_2025_WOF_F2_5_plant_60 | P405: =VLOOKUP(C405,CU_ARS_2025_WOF_F2!$A$2:$K$673,3,FALSE) -> CU_ARS_2025_WOF_F2_5 | Q405: =VLOOKUP(C405,CU_ARS_2025_WOF_F2!$A$2:$K$673,4,FALSE) -> CU_ARS_2025_WOF_cross_54 | R405: =VLOOKUP(C405,CU_ARS_2025_WOF_F2!$A$2:$K$673,5,FALSE) -> 5 | S405: =VLOOKUP(C405,CU_ARS_2025_WOF_F2!$A$2:$K$673,6,FALSE) -> 1 | T405: =VLOOKUP(C405,CU_ARS_2025_WOF_F2!$A$2:$K$673,7,FALSE) -> 0 | U405: =VLOOKUP(C405,CU_ARS_2025_WOF_F2!$A$2:$K$673,8,FALSE) -> 1 | V405: =VLOOKUP(C405,CU_ARS_2025_WOF_F2!$A$2:$K$673,9,FALSE) -> 0 | W405: =VLOOKUP(C405,CU_ARS_2025_WOF_F2!$A$2:$K$673,10,FALSE) -> 0 | X405: =VLOOKUP(C405,CU_ARS_2025_WOF_F2!$A$2:$K$673,11,FALSE) -> 60 | Y405: =VLOOKUP(Q405,cross_pedigree!$A$2:$B$23,2,FALSE) -> Gerard 227/NF13-4126-4_3
A406: Jannink | B406: USDA-Ithaca2025-O3K_01-07 | C406: 753993 | D406: 5 | E406: =O406 -> CU_ARS_2025_WOF_F2_5_plant_62 | F406: E03 | G406: 21 | I406: Gerard 227/NF13-4126-4_3 | J406: F2 | N406: =VLOOKUP(C406,CU_ARS_2025_WOF_F2!$A$2:$K$673,2,FALSE) -> CU_ARS_2025_WOF_F2_5_plant_62 | O406: =VLOOKUP(C406,CU_ARS_2025_WOF_F2!$A$2:$K$673,2,FALSE) -> CU_ARS_2025_WOF_F2_5_plant_62 | P406: =VLOOKUP(C406,CU_ARS_2025_WOF_F2!$A$2:$K$673,3,FALSE) -> CU_ARS_2025_WOF_F2_5 | Q406: =VLOOKUP(C406,CU_ARS_2025_WOF_F2!$A$2:$K$673,4,FALSE) -> CU_ARS_2025_WOF_cross_54 | R406: =VLOOKUP(C406,CU_ARS_2025_WOF_F2!$A$2:$K$673,5,FALSE) -> 5 | S406: =VLOOKUP(C406,CU_ARS_2025_WOF_F2!$A$2:$K$673,6,FALSE) -> 1 | T406: =VLOOKUP(C406,CU_ARS_2025_WOF_F2!$A$2:$K$673,7,FALSE) -> 0 | U406: =VLOOKUP(C406,CU_ARS_2025_WOF_F2!$A$2:$K$673,8,FALSE) -> 1 | V406: =VLOOKUP(C406,CU_ARS_2025_WOF_F2!$A$2:$K$673,9,FALSE) -> 0 | W406: =VLOOKUP(C406,CU_ARS_2025_WOF_F2!$A$2:$K$673,10,FALSE) -> 0 | X406: =VLOOKUP(C406,CU_ARS_2025_WOF_F2!$A$2:$K$673,11,FALSE) -> 62 | Y406: =VLOOKUP(Q406,cross_pedigree!$A$2:$B$23,2,FALSE) -> Gerard 227/NF13-4126-4_3
... A481: Jannink | B481: USDA-Ithaca2025-O3K_01-07 | C481: 753485 | D481: 5 | E481: =O481 -> CU_ARS_2025_WOF_F2_4_plant_71 | F481: H12 | G481: 96 | I481: Gerard 227/AURORA | J481: F2 | N481: =VLOOKUP(C481,CU_ARS_2025_WOF_F2!$A$2:$K$673,2,FALSE) -> CU_ARS_2025_WOF_F2_4_plant_71 | O481: =VLOOKUP(C481,CU_ARS_2025_WOF_F2!$A$2:$K$673,2,FALSE) -> CU_ARS_2025_WOF_F2_4_plant_71 | P481: =VLOOKUP(C481,CU_ARS_2025_WOF_F2!$A$2:$K$673,3,FALSE) -> CU_ARS_2025_WOF_F2_4 | Q481: =VLOOKUP(C481,CU_ARS_2025_WOF_F2!$A$2:$K$673,4,FALSE) -> CU_ARS_2025_WOF_cross_19 | R481: =VLOOKUP(C481,CU_ARS_2025_WOF_F2!$A$2:$K$673,5,FALSE) -> 4 | S481: =VLOOKUP(C481,CU_ARS_2025_WOF_F2!$A$2:$K$673,6,FALSE) -> 1 | T481: =VLOOKUP(C481,CU_ARS_2025_WOF_F2!$A$2:$K$673,7,FALSE) -> 0 | U481: =VLOOKUP(C481,CU_ARS_2025_WOF_F2!$A$2:$K$673,8,FALSE) -> 1 | V481: =VLOOKUP(C481,CU_ARS_2025_WOF_F2!$A$2:$K$673,9,FALSE) -> 0 | W481: =VLOOKUP(C481,CU_ARS_2025_WOF_F2!$A$2:$K$673,10,FALSE) -> 0 | X481: =VLOOKUP(C481,CU_ARS_2025_WOF_F2!$A$2:$K$673,11,FALSE) -> 71 | Y481: =VLOOKUP(Q481,cross_pedigree!$A$2:$B$23,2,FALSE) -> Gerard 227/AURORA
...

Sheet cross_pedigree
A1: Cross Unique ID | B1: Cross Combination
A2: CU_ARS_2025_WOF_cross_1 | B2: AURORA/AWNLESS_CURLED
A3: CU_ARS_2025_WOF_cross_4 | B3: NF01404A/PA8014-840
A4: CU_ARS_2025_WOF_cross_19 | B4: Gerard 227/AURORA
A5: CU_ARS_2025_WOF_cross_23 | B5: AWNLESS_CURLED/NC21-6429
A6: CU_ARS_2025_WOF_cross_24 | B6: SEGER|PI306405/NC21-6429
A7: CU_ARS_2025_WOF_cross_25 | B7: TRISPERNIA|CIAV5100/NF97405B2
A8: CU_ARS_2025_WOF_cross_29 | B8: NC21-6429/AURORA
A9: CU_ARS_2025_WOF_cross_31 | B9: NC21-6429/WINTER_TURF|CIAV996
A10: CU_ARS_2025_WOF_cross_35 | B10: NC21-6429/NF97405B2
A11: CU_ARS_2025_WOF_cross_36 | B11: WESTFINNISCHER_SCHWARZ/NF97405B2
A12: CU_ARS_2025_WOF_cross_42 | B12: DOMACA_ZOB/NF97405B2
... A23: CU_ARS_2025_WOF_cross_87 | B23: Gerard 227/PA8014-840

Sheet CU_ARS_2025_WOF_F2
A1: plant_id | B1: plant_name | C1: plot_name | D1: accession_name | E1: plot_number | F1: block_number | G1: is_a_control | H1: rep_number | I1: row_number | J1: col_number | K1: plant_number
A2: 753780 | B2: CU_ARS_2025_WOF_F2_1_plant_1 | C2: CU_ARS_2025_WOF_F2_1 | D2: CU_ARS_2025_WOF_cross_55 | E2: 1 | F2: 1 | H2: 1 | K2: 1
A3: 753781 | B3: CU_ARS_2025_WOF_F2_1_plant_2 | C3: CU_ARS_2025_WOF_F2_1 | D3: CU_ARS_2025_WOF_cross_55 | E3: 1 | F3: 1 | H3: 1 | K3: 2
A4: 753782 | B4: CU_ARS_2025_WOF_F2_1_plant_3 | C4: CU_ARS_2025_WOF_F2_1 | D4: CU_ARS_2025_WOF_cross_55 | E4: 1 | F4: 1 | H4: 1 | K4: 3
A5: 753783 | B5: CU_ARS_2025_WOF_F2_1_plant_4 | C5: CU_ARS_2025_WOF_F2_1 | D5: CU_ARS_2025_WOF_cross_55 | E5: 1 | F5: 1 | H5: 1 | K5: 4
A6: 753784 | B6: CU_ARS_2025_WOF_F2_1_plant_5 | C6: CU_ARS_2025_WOF_F2_1 | D6: CU_ARS_2025_WOF_cross_55 | E6: 1 | F6: 1 | H6: 1 | K6: 5
A7: 753785 | B7: CU_ARS_2025_WOF_F2_1_plant_6 | C7: CU_ARS_2025_WOF_F2_1 | D7: CU_ARS_2025_WOF_cross_55 | E7: 1 | F7: 1 | H7: 1 | K7: 6
A8: 753786 | B8: CU_ARS_2025_WOF_F2_1_plant_7 | C8: CU_ARS_2025_WOF_F2_1 | D8: CU_ARS_2025_WOF_cross_55 | E8: 1 | F8: 1 | H8: 1 | K8: 7
A9: 753787 | B9: CU_ARS_2025_WOF_F2_1_plant_8 | C9: CU_ARS_2025_WOF_F2_1 | D9: CU_ARS_2025_WOF_cross_55 | E9: 1 | F9: 1 | H9: 1 | K9: 8
A10: 753788 | B10: CU_ARS_2025_WOF_F2_1_plant_9 | C10: CU_ARS_2025_WOF_F2_1 | D10: CU_ARS_2025_WOF_cross_55 | E10: 1 | F10: 1 | H10: 1 | K10: 9
A11: 753789 | B11: CU_ARS_2025_WOF_F2_1_plant_10 | C11: CU_ARS_2025_WOF_F2_1 | D11: CU_ARS_2025_WOF_cross_55 | E11: 1 | F11: 1 | H11: 1 | K11: 10
A12: 753790 | B12: CU_ARS_2025_WOF_F2_1_plant_11 | C12: CU_ARS_2025_WOF_F2_1 | D12: CU_ARS_2025_WOF_cross_55 | E12: 1 | F12: 1 | H12: 1 | K12: 11
A13: 753791 | B13: CU_ARS_2025_WOF_F2_1_plant_12 | C13: CU_ARS_2025_WOF_F2_1 | D13: CU_ARS_2025_WOF_cross_55 | E13: 1 | F13: 1 | H13: 1 | K13: 12
... A673: 754014 | B673: CU_ARS_2025_WOF_P_19_plant_3 | C673: CU_ARS_2025_WOF_P_19 | D673: SEGER|PI306405 | E673: 19 | F673: 1 | H673: 1 | K673: 3

Sheet update sample
A1: Collaborator | B1: Project | C1: Sample_ID | D1: Plate_ID | E1: Sample_Name | F1: Well | G1: Sample # | H1: Trait | I1: Pedigree | J1: Generation | K1: Organism | L1: Comments | M1: PlantSource | N1: plate_well | O1: plate_well | P1: Sample ID
A2: Jannink | B2: USDA-Ithaca2025-O3K_01-07 | C2: =IF(N2=O2,P2,"error") -> 753820 | D2: 1 | F2: C05 | G2: 35 | N2: =_xlfn.CONCAT(D2,"_",F2) -> 1_C05 | O2: 1_C05 | P2: 753820
A3: Jannink | B3: USDA-Ithaca2025-O3K_01-07 | C3: =IF(N3=O3,P3,"error") -> 753821 | D3: 1 | F3: D05 | G3: 36 | N3: =_xlfn.CONCAT(D3,"_",F3) -> 1_D05 | O3: 1_D05 | P3: 753821
A4: Jannink | B4: USDA-Ithaca2025-O3K_01-07 | C4: =IF(N4=O4,P4,"error") -> 753822 | D4: 1 | F4: E05 | G4: 37 | N4: =_xlfn.CONCAT(D4,"_",F4) -> 1_E05 | O4: 1_E05 | P4: 753822
A5: Jannink | B5: USDA-Ithaca2025-O3K_01-07 | C5: =IF(N5=O5,P5,"error") -> 753823 | D5: 1 | F5: F05 | G5: 38 | N5: =_xlfn.CONCAT(D5,"_",F5) -> 1_F05 | O5: 1_F05 | P5: 753823
A6: Jannink | B6: USDA-Ithaca2025-O3K_01-07 | C6: =IF(N6=O6,P6,"error") -> 753824 | D6: 1 | F6: D06 | G6: 44 | N6: =_xlfn.CONCAT(D6,"_",F6) -> 1_D06 | O6: 1_D06 | P6: 753824
A7: Jannink | B7: USDA-Ithaca2025-O3K_01-07 | C7: =IF(N7=O7,P7,"error") -> 753836 | D7: 1 | F7: E06 | G7: 45 | N7: =_xlfn.CONCAT(D7,"_",F7) -> 1_E06 | O7: 1_E06 | P7: 753836
A8: Jannink | B8: USDA-Ithaca2025-O3K_01-07 | C8: =IF(N8=O8,P8,"error") -> 753837 | D8: 1 | F8: F06 | G8: 46 | N8: =_xlfn.CONCAT(D8,"_",F8) -> 1_F06 | O8: 1_F06 | P8: 753837
A9: Jannink | B9: USDA-Ithaca2025-O3K_01-07 | C9: =IF(N9=O9,P9,"error") -> 753838 | D9: 1 | F9: F07 | G9: 54 | N9: =_xlfn.CONCAT(D9,"_",F9) -> 1_F07 | O9: 1_F07 | P9: 753838
A10: Jannink | B10: USDA-Ithaca2025-O3K_01-07 | C10: =IF(N10=O10,P10,"error") -> 753839 | D10: 1 | F10: G07 | G10: 55 | N10: =_xlfn.CONCAT(D10,"_",F10) -> 1_G07 | O10: 1_G07 | P10: 753839
A11: Jannink | B11: USDA-Ithaca2025-O3K_01-07 | C11: =IF(N11=O11,P11,"error") -> 753840 | D11: 1 | F11: H07 | G11: 56 | N11: =_xlfn.CONCAT(D11,"_",F11) -> 1_H07 | O11: 1_H07 | P11: 753840
A12: Jannink | B12: USDA-Ithaca2025-O3K_01-07 | C12: =IF(N12=O12,P12,"error") -> 753510 | D12: 1 | F12: A08 | G12: 57 | N12: =_xlfn.CONCAT(D12,"_",F12) -> 1_A08 | O12: 1_A08 | P12: 753510
A13: Jannink | B13: USDA-Ithaca2025-O3K_01-07 | C13: =IF(N13=O13,P13,"error") -> 753511 | D13: 1 | F13: B08 | G13: 58 | N13: =_xlfn.CONCAT(D13,"_",F13) -> 1_B08 | O13: 1_B08 | P13: 753511
... A35: Jannink | B35: USDA-Ithaca2025-O3K_01-07 | C35: =IF(N35=O35,P35,"error") -> 754073 | D35: 5 | F35: A02 | G35: 09 | N35: =_xlfn.CONCAT(D35,"_",F35) -> 5_A02 | O35: 5_A02 | P35: 754073
A36: Jannink | B36: USDA-Ithaca2025-O3K_01-07 | C36: =IF(N36=O36,P36,"error") -> 754074 | D36: 5 | F36: B02 | G36: 10 | N36: =_xlfn.CONCAT(D36,"_",F36) -> 5_B02 | O36: 5_B02 | P36: 754074
A37: Jannink | B37: USDA-Ithaca2025-O3K_01-07 | C37: =IF(N37=O37,P37,"error") -> 754075 | D37: 5 | F37: C02 | G37: 11 | N37: =_xlfn.CONCAT(D37,"_",F37) -> 5_C02 | O37: 5_C02 | P37: 754075
A38: Jannink | B38: USDA-Ithaca2025-O3K_01-07 | C38: =IF(N38=O38,P38,"error") -> 753998 | D38: 5 | F38: D02 | G38: 12 | N38: =_xlfn.CONCAT(D38,"_",F38) -> 5_D02 | O38: 5_D02 | P38: 753998
A39: Jannink | B39: USDA-Ithaca2025-O3K_01-07 | C39: =IF(N39=O39,P39,"error") -> 753987 | D39: 5 | F39: E02 | G39: 13 | N39: =_xlfn.CONCAT(D39,"_",F39) -> 5_E02 | O39: 5_E02 | P39: 753987
A40: Jannink | B40: USDA-Ithaca2025-O3K_01-07 | C40: =IF(N40=O40,P40,"error") -> 753988 | D40: 5 | F40: F02 | G40: 14 | N40: =_xlfn.CONCAT(D40,"_",F40) -> 5_F02 | O40: 5_F02 | P40: 753988
A41: Jannink | B41: USDA-Ithaca2025-O3K_01-07 | C41: =IF(N41=O41,P41,"error") -> 753991 | D41: 5 | F41: D03 | G41: 20 | N41: =_xlfn.CONCAT(D41,"_",F41) -> 5_D03 | O41: 5_D03 | P41: 753991
A42: Jannink | B42: USDA-Ithaca2025-O3K_01-07 | C42: =IF(N42=O42,P42,"error") -> 753993 | D42: 5 | F42: E03 | G42: 21 | N42: =_xlfn.CONCAT(D42,"_",F42) -> 5_E03 | O42: 5_E03 | P42: 753993
A43: Jannink | B43: USDA-Ithaca2025-O3K_01-07 | C43: =IF(N43=O43,P43,"error") -> 753992 | D43: 5 | F43: F03 | G43: 22 | N43: =_xlfn.CONCAT(D43,"_",F43) -> 5_F03 | O43: 5_F03 | P43: 753992
A44: Jannink | B44: USDA-Ithaca2025-O3K_01-07 | C44: =IF(N44=O44,P44,"error") -> 754000 | D44: 5 | F44: G03 | G44: 23 | N44: =_xlfn.CONCAT(D44,"_",F44) -> 5_G03 | O44: 5_G03 | P44: 754000
A45: Jannink | B45: USDA-Ithaca2025-O3K_01-07 | C45: =IF(N45=O45,P45,"error") -> 754001 | D45: 5 | F45: H03 | G45: 24 | N45: =_xlfn.CONCAT(D45,"_",F45) -> 5_H03 | O45: 5_H03 | P45: 754001
A46: Jannink | B46: USDA-Ithaca2025-O3K_01-07 | C46: =IF(N46=O46,P46,"error") -> 753999 | D46: 7 | F46: G10 | G46: 79 | N46: =_xlfn.CONCAT(D46,"_",F46) -> 7_G10 | O46: 7_G10 | P46: 753999
A47: Jannink | B47: USDA-Ithaca2025-O3K_01-07 | C47: =IF(N47=O47,P47,"error") -> 753884 | D47: 7 | F47: H10 | G47: 80 | N47: =_xlfn.CONCAT(D47,"_",F47) -> 7_H10 | O47: 7_H10 | P47: 753884
... A63: Jannink | B63: USDA-Ithaca2025-O3K_01-07 | C63: =IF(N63=O63,P63,"error") -> 753588 | D63: 7 | F63: H12 | G63: 96 | N63: =_xlfn.CONCAT(D63,"_",F63) -> 7_H12 | O63: 7_H12 | P63: 753588
A64: Jannink | B64: USDA-Ithaca2025-O3K_01-07 | C64: 753635 | D64: 1 | F64: A01 | G64: 1 | N64: =_xlfn.CONCAT(D64,"_",F64) -> 1_A01
A65: Jannink | B65: USDA-Ithaca2025-O3K_01-07 | C65: 753857 | D65: 1 | F65: B01 | G65: 2 | N65: =_xlfn.CONCAT(D65,"_",F65) -> 1_B01
A66: Jannink | B66: USDA-Ithaca2025-O3K_01-07 | C66: 754009 | D66: 1 | F66: C01 | G66: 3 | N66: =_xlfn.CONCAT(D66,"_",F66) -> 1_C01
A67: Jannink | B67: USDA-Ithaca2025-O3K_01-07 | C67: 754008 | D67: 1 | F67: D01 | G67: 4 | N67: =_xlfn.CONCAT(D67,"_",F67) -> 1_D01
A68: Jannink | B68: USDA-Ithaca2025-O3K_01-07 | C68: 754005 | D68: 1 | F68: E01 | G68: 5 | N68: =_xlfn.CONCAT(D68,"_",F68) -> 1_E01
A69: Jannink | B69: USDA-Ithaca2025-O3K_01-07 | C69: 753636 | D69: 1 | F69: F01 | G69: 6 | N69: =_xlfn.CONCAT(D69,"_",F69) -> 1_F01
A70: Jannink | B70: USDA-Ithaca2025-O3K_01-07 | C70: 753856 | D70: 1 | F70: G01 | G70: 7 | N70: =_xlfn.CONCAT(D70,"_",F70) -> 1_G01
A71: Jannink | B71: USDA-Ithaca2025-O3K_01-07 | C71: 754011 | D71: 1 | F71: H01 | G71: 8 | N71: =_xlfn.CONCAT(D71,"_",F71) -> 1_H01
A72: Jannink | B72: USDA-Ithaca2025-O3K_01-07 | C72: 754007 | D72: 1 | F72: A02 | G72: 9 | N72: =_xlfn.CONCAT(D72,"_",F72) -> 1_A02
A73: Jannink | B73: USDA-Ithaca2025-O3K_01-07 | C73: 754004 | D73: 1 | F73: B02 | G73: 10 | N73: =_xlfn.CONCAT(D73,"_",F73) -> 1_B02
A74: Jannink | B74: USDA-Ithaca2025-O3K_01-07 | C74: 753637 | D74: 1 | F74: C02 | G74: 11 | N74: =_xlfn.CONCAT(D74,"_",F74) -> 1_C02
A75: Jannink | B75: USDA-Ithaca2025-O3K_01-07 | C75: 753855 | D75: 1 | F75: D02 | G75: 12 | N75: =_xlfn.CONCAT(D75,"_",F75) -> 1_D02
... A422: Jannink | B422: USDA-Ithaca2025-O3K_01-07 | C422: 753995 | D422: 5 | F422: C01 | G422: 03 | N422: =_xlfn.CONCAT(D422,"_",F422) -> 5_C01
...

Sheet orig sampl with duplicate
A1: Sample_ID | B1: Collaborator | C1: Project | D1: Plate_ID | E1: Sample_Name | F1: Well | G1: Sample # | H1: Trait | I1: Pedigree | J1: Generation | K1: Organism | L1: Comments | M1: PlantSource
A2: 753635 | B2: Jannink | C2: USDA-Ithaca2025-O3K_01-07 | D2: 1 | F2: A01 | G2: 1
A3: 753857 | B3: Jannink | C3: USDA-Ithaca2025-O3K_01-07 | D3: 1 | F3: B01 | G3: 2
A4: 754009 | B4: Jannink | C4: USDA-Ithaca2025-O3K_01-07 | D4: 1 | F4: C01 | G4: 3
A5: 754008 | B5: Jannink | C5: USDA-Ithaca2025-O3K_01-07 | D5: 1 | F5: D01 | G5: 4
A6: 754005 | B6: Jannink | C6: USDA-Ithaca2025-O3K_01-07 | D6: 1 | F6: E01 | G6: 5
A7: 753636 | B7: Jannink | C7: USDA-Ithaca2025-O3K_01-07 | D7: 1 | F7: F01 | G7: 6
A8: 753856 | B8: Jannink | C8: USDA-Ithaca2025-O3K_01-07 | D8: 1 | F8: G01 | G8: 7
A9: 754011 | B9: Jannink | C9: USDA-Ithaca2025-O3K_01-07 | D9: 1 | F9: H01 | G9: 8
A10: 754007 | B10: Jannink | C10: USDA-Ithaca2025-O3K_01-07 | D10: 1 | F10: A02 | G10: 9
A11: 754004 | B11: Jannink | C11: USDA-Ithaca2025-O3K_01-07 | D11: 1 | F11: B02 | G11: 10
A12: 753637 | B12: Jannink | C12: USDA-Ithaca2025-O3K_01-07 | D12: 1 | F12: C02 | G12: 11
A13: 753855 | B13: Jannink | C13: USDA-Ithaca2025-O3K_01-07 | D13: 1 | F13: D02 | G13: 12
... A394: 753999 | B394: Jannink | C394: USDA-Ithaca2025-O3K_01-07 | D394: 5 | F394: A02 | G394: 09
A395: 754015 | B395: Jannink | C395: USDA-Ithaca2025-O3K_01-07 | D395: 5 | F395: B02 | G395: 10
A396: 754016 | B396: Jannink | C396: USDA-Ithaca2025-O3K_01-07 | D396: 5 | F396: C02 | G396: 11
A397: 754017 | B397: Jannink | C397: USDA-Ithaca2025-O3K_01-07 | D397: 5 | F397: D02 | G397: 12
A398: 754018 | B398: Jannink | C398: USDA-Ithaca2025-O3K_01-07 | D398: 5 | F398: E02 | G398: 13
A399: 754019 | B399: Jannink | C399: USDA-Ithaca2025-O3K_01-07 | D399: 5 | F399: F02 | G399: 14
A400: 754027 | B400: Jannink | C400: USDA-Ithaca2025-O3K_01-07 | D400: 5 | F400: G02 | G400: 15
A401: 754026 | B401: Jannink | C401: USDA-Ithaca2025-O3K_01-07 | D401: 5 | F401: H02 | G401: 16
A402: 754025 | B402: Jannink | C402: USDA-Ithaca2025-O3K_01-07 | D402: 5 | F402: A03 | G402: 17
A403: 754020 | B403: Jannink | C403: USDA-Ithaca2025-O3K_01-07 | D403: 5 | F403: B03 | G403: 18
A404: 754021 | B404: Jannink | C404: USDA-Ithaca2025-O3K_01-07 | D404: 5 | F404: C03 | G404: 19
A405: 754015 | B405: Jannink | C405: USDA-Ithaca2025-O3K_01-07 | D405: 5 | F405: D03 | G405: 20
A406: 754016 | B406: Jannink | C406: USDA-Ithaca2025-O3K_01-07 | D406: 5 | F406: E03 | G406: 21
... A481: 753485 | B481: Jannink | C481: USDA-Ithaca2025-O3K_01-07 | D481: 5 | F481: H12 | G481: 96
A482: 753479 | B482: Jannink | C482: USDA-Ithaca2025-O3K_01-07 | D482: 6 | F482: A01 | G482: 01
A483: 753480 | B483: Jannink | C483: USDA-Ithaca2025-O3K_01-07 | D483: 6 | F483: B01 | G483: 02
A484: 753481 | B484: Jannink | C484: USDA-Ithaca2025-O3K_01-07 | D484: 6 | F484: C01 | G484: 03
A485: 753482 | B485: Jannink | C485: USDA-Ithaca2025-O3K_01-07 | D485: 6 | F485: D01 | G485: 04
A486: 753483 | B486: Jannink | C486: USDA-Ithaca2025-O3K_01-07 | D486: 6 | F486: E01 | G486: 05
A487: 753780 | B487: Jannink | C487: USDA-Ithaca2025-O3K_01-07 | D487: 6 | F487: F01 | G487: 06
A488: 753781 | B488: Jannink | C488: USDA-Ithaca2025-O3K_01-07 | D488: 6 | F488: G01 | G488: 07
A489: 753782 | B489: Jannink | C489: USDA-Ithaca2025-O3K_01-07 | D489: 6 | F489: H01 | G489: 08
A490: 753783 | B490: Jannink | C490: USDA-Ithaca2025-O3K_01-07 | D490: 6 | F490: A02 | G490: 09
A491: 753784 | B491: Jannink | C491: USDA-Ithaca2025-O3K_01-07 | D491: 6 | F491: B02 | G491: 10
A492: 753792 | B492: Jannink | C492: USDA-Ithaca2025-O3K_01-07 | D492: 6 | F492: C02 | G492: 11
A493: 753791 | B493: Jannink | C493: USDA-Ithaca2025-O3K_01-07 | D493: 6 | F493: D02 | G493: 12
A494: 753790 | B494: Jannink | C494: USDA-Ithaca2025-O3K_01-07 | D494: 6 | F494: E02 | G494: 13
...

Sheet updated genotyping plate sampl 
A1: Well | B1: Sample ID | C1: Plate ID | D1: Sample # | E1: plate_well
A2: C05 | B2: 753820 | C2: 1 | D2: 35 | E2: =_xlfn.CONCAT(C2,"_",A2) -> 1_C05
A3: D05 | B3: 753821 | C3: 1 | D3: 36 | E3: =_xlfn.CONCAT(C3,"_",A3) -> 1_D05
A4: E05 | B4: 753822 | C4: 1 | D4: 37 | E4: =_xlfn.CONCAT(C4,"_",A4) -> 1_E05
A5: F05 | B5: 753823 | C5: 1 | D5: 38 | E5: =_xlfn.CONCAT(C5,"_",A5) -> 1_F05
A6: D06 | B6: 753824 | C6: 1 | D6: 44 | E6: =_xlfn.CONCAT(C6,"_",A6) -> 1_D06
A7: E06 | B7: 753836 | C7: 1 | D7: 45 | E7: =_xlfn.CONCAT(C7,"_",A7) -> 1_E06
A8: F06 | B8: 753837 | C8: 1 | D8: 46 | E8: =_xlfn.CONCAT(C8,"_",A8) -> 1_F06
A9: F07 | B9: 753838 | C9: 1 | D9: 54 | E9: =_xlfn.CONCAT(C9,"_",A9) -> 1_F07
A10: G07 | B10: 753839 | C10: 1 | D10: 55 | E10: =_xlfn.CONCAT(C10,"_",A10) -> 1_G07
A11: H07 | B11: 753840 | C11: 1 | D11: 56 | E11: =_xlfn.CONCAT(C11,"_",A11) -> 1_H07
A12: A08 | B12: 753510 | C12: 1 | D12: 57 | E12: =_xlfn.CONCAT(C12,"_",A12) -> 1_A08
A13: B08 | B13: 753511 | C13: 1 | D13: 58 | E13: =_xlfn.CONCAT(C13,"_",A13) -> 1_B08
... A63: H12 | B63: 753588 | C63: 7 | D63: 96 | E63: =_xlfn.CONCAT(C63,"_",A63) -> 7_H12
