Workbook

Sheet Sheet1
A1: AURORA-Cornell_WinterOatPeaIntercrop_2024_Ithaca-PLOT_24 | B1: =VLOOKUP(A1,Sheet5!$A$1:$B$53,2,FALSE) -> WOP_2026_selections
A2: Clav 4476-Cornell_WinterOatPeaIntercrop_2024_Ithaca-PLOT_240 | B2: =VLOOKUP(A2,Sheet5!$A$1:$B$53,2,FALSE) -> #N/A
A3: Clav 6982-Cornell_WinterOatPeaIntercrop_2024_Ithaca-PLOT_235 | B3: =VLOOKUP(A3,Sheet5!$A$1:$B$53,2,FALSE) -> #N/A
A4: Clav 7618-Cornell_WinterOatPeaIntercrop_2024_Ithaca-PLOT_123 | B4: =VLOOKUP(A4,Sheet5!$A$1:$B$53,2,FALSE) -> #N/A
A5: FLLA11019-8-Cornell_WinterOatPeaIntercrop_2024_Ithaca-PLOT_356 | B5: =VLOOKUP(A5,Sheet5!$A$1:$B$53,2,FALSE) -> #N/A
A6: FLLA16083-25-Cornell_WinterOatPeaIntercrop_2024_Ithaca-PLOT_351 | B6: =VLOOKUP(A6,Sheet5!$A$1:$B$53,2,FALSE) -> #N/A
A7: FLLA17069-52-Cornell_WinterOatPeaIntercrop_2024_Ithaca-PLOT_30 | B7: =VLOOKUP(A7,Sheet5!$A$1:$B$53,2,FALSE) -> #N/A
A8: FLLA17069-53-Cornell_WinterOatPeaIntercrop_2024_Ithaca-PLOT_34 | B8: =VLOOKUP(A8,Sheet5!$A$1:$B$53,2,FALSE) -> #N/A
A9: FLLA17069-54-Cornell_WinterOatPeaIntercrop_2024_Ithaca-PLOT_102 | B9: =VLOOKUP(A9,Sheet5!$A$1:$B$53,2,FALSE) -> #N/A
A10: FLLA17069-65-Cornell_WinterOatPeaIntercrop_2024_Ithaca-PLOT_113 | B10: =VLOOKUP(A10,Sheet5!$A$1:$B$53,2,FALSE) -> #N/A
A11: FLLA17088-61-Cornell_WinterOatPeaIntercrop_2024_Ithaca-PLOT_339 | B11: =VLOOKUP(A11,Sheet5!$A$1:$B$53,2,FALSE) -> WOP_2026_selections
A12: FLLA17088-77-Cornell_WinterOatPeaIntercrop_2024_Ithaca-PLOT_48 | B12: =VLOOKUP(A12,Sheet5!$A$1:$B$53,2,FALSE) -> WOP_2026_selections
... A94: TX19CAS0058-Cornell_WinterOatPeaIntercrop_2024_Ithaca-PLOT_280 | B94: =VLOOKUP(A94,Sheet5!$A$1:$B$53,2,FALSE) -> #N/A

Sheet Sheet2
A1: OZARK|POGI-Cornell_WinterOatPeaIntercrop_2024_Ithaca-PLOT_204
A2: NC21-6492-Cornell_WinterOatPeaIntercrop_2024_Ithaca-PLOT_128
A3: NF12AS-73-4_3-Cornell_WinterOatPeaIntercrop_2024_Ithaca-PLOT_242
A4: NF13-4214-4_5-Cornell_WinterOatPeaIntercrop_2024_Ithaca-PLOT_169
A5: PA7617-3658-Cornell_WinterOatPeaIntercrop_2024_Ithaca-PLOT_54
A6: PA7617-3460-Cornell_WinterOatPeaIntercrop_2024_Ithaca-PLOT_212
A7: NF13-4214-4_1-Cornell_WinterOatPeaIntercrop_2024_Ithaca-PLOT_156
A8: NF13-4157-4_2-Cornell_WinterOatPeaIntercrop_2024_Ithaca-PLOT_81
A9: NC20-4452-Cornell_WinterOatPeaIntercrop_2024_Ithaca-PLOT_98
A10: NC21-6610-Cornell_WinterOatPeaIntercrop_2024_Ithaca-PLOT_99
A11: NF99414-Cornell_WinterOatPeaIntercrop_2024_Ithaca-PLOT_378
A12: NF13-4083-4_6-Cornell_WinterOatPeaIntercrop_2024_Ithaca-PLOT_83
... A47: NC21-6497-Cornell_WinterOatPeaIntercrop_2024_Ithaca-PLOT_65

Sheet Sheet3
A1: NF12AS-73-4_3-Cornell_WinterOatPeaIntercrop_2024_Ithaca-PLOT_241 | B1: 668
A2: OZARK|POGI-Cornell_WinterOatPeaIntercrop_2024_Ithaca-PLOT_203 | B2: 687
A3: NC21-6492-Cornell_WinterOatPeaIntercrop_2024_Ithaca-PLOT_127 | B3: 711
A4: PA7617-3658-Cornell_WinterOatPeaIntercrop_2024_Ithaca-PLOT_53 | B4: 542
A5: PA7617-3658-Cornell_WinterOatPeaIntercrop_2024_Ithaca-PLOT_201 | B5: 772
A6: PA7617-3658-Cornell_WinterOatPeaIntercrop_2024_Ithaca-PLOT_202 | B6: 733

Sheet Sheet4
A1: NF01401B-Cornell_WinterOatPeaIntercrop_2024_Ithaca-PLOT_2 | B1: =VLOOKUP(A1,Sheet6!$A$1:$B$94,2,FALSE) -> #N/A
A2: NF502_5-Cornell_WinterOatPeaIntercrop_2024_Ithaca-PLOT_4 | B2: =VLOOKUP(A2,Sheet6!$A$1:$B$94,2,FALSE) -> #N/A
A3: NF502_5-Cornell_WinterOatPeaIntercrop_2024_Ithaca-PLOT_3 | B3: =VLOOKUP(A3,Sheet6!$A$1:$B$94,2,FALSE) -> WOP_2026_not_selected
A4: NF01401B-Cornell_WinterOatPeaIntercrop_2024_Ithaca-PLOT_1 | B4: =VLOOKUP(A4,Sheet6!$A$1:$B$94,2,FALSE) -> #N/A
A5: NC20-4452-Cornell_WinterOatPeaIntercrop_2024_Ithaca-PLOT_5 | B5: =VLOOKUP(A5,Sheet6!$A$1:$B$94,2,FALSE) -> #N/A
A6: FLLA17088-77-Cornell_WinterOatPeaIntercrop_2024_Ithaca-PLOT_7 | B6: =VLOOKUP(A6,Sheet6!$A$1:$B$94,2,FALSE) -> #N/A
A7: FLLA17088-77-Cornell_WinterOatPeaIntercrop_2024_Ithaca-PLOT_8 | B7: =VLOOKUP(A7,Sheet6!$A$1:$B$94,2,FALSE) -> #N/A
A8: NC20-4452-Cornell_WinterOatPeaIntercrop_2024_Ithaca-PLOT_6 | B8: =VLOOKUP(A8,Sheet6!$A$1:$B$94,2,FALSE) -> #N/A
A9: TX18OCS9125-Cornell_WinterOatPeaIntercrop_2024_Ithaca-PLOT_10 | B9: =VLOOKUP(A9,Sheet6!$A$1:$B$94,2,FALSE) -> WOP_2026_selections
A10: TX18OCS9125-Cornell_WinterOatPeaIntercrop_2024_Ithaca-PLOT_9 | B10: =VLOOKUP(A10,Sheet6!$A$1:$B$94,2,FALSE) -> #N/A
A11: NO_OATS_PLANTED-Cornell_WinterOatPeaIntercrop_2024_Ithaca-PLOT_11 | B11: =VLOOKUP(A11,Sheet6!$A$1:$B$94,2,FALSE) -> #N/A
A12: NC21-6429-Cornell_WinterOatPeaIntercrop_2024_Ithaca-PLOT_15 | B12: =VLOOKUP(A12,Sheet6!$A$1:$B$94,2,FALSE) -> #N/A
... A379: AURORA-Cornell_WinterOatPeaIntercrop_2024_Ithaca-PLOT_24 | B379: =VLOOKUP(A379,Sheet6!$A$1:$B$94,2,FALSE) -> WOP_2026_selections

Sheet Sheet5
A1: OZARK|POGI-Cornell_WinterOatPeaIntercrop_2024_Ithaca-PLOT_204 | B1: WOP_2026_selections
A2: NC21-6492-Cornell_WinterOatPeaIntercrop_2024_Ithaca-PLOT_128 | B2: WOP_2026_selections
A3: NF12AS-73-4_3-Cornell_WinterOatPeaIntercrop_2024_Ithaca-PLOT_242 | B3: WOP_2026_selections
A4: NF13-4214-4_5-Cornell_WinterOatPeaIntercrop_2024_Ithaca-PLOT_169 | B4: WOP_2026_selections
A5: PA7617-3658-Cornell_WinterOatPeaIntercrop_2024_Ithaca-PLOT_54 | B5: WOP_2026_selections
A6: PA7617-3460-Cornell_WinterOatPeaIntercrop_2024_Ithaca-PLOT_212 | B6: WOP_2026_selections
A7: NF13-4214-4_1-Cornell_WinterOatPeaIntercrop_2024_Ithaca-PLOT_156 | B7: WOP_2026_selections
A8: NF13-4157-4_2-Cornell_WinterOatPeaIntercrop_2024_Ithaca-PLOT_81 | B8: WOP_2026_selections
A9: NC20-4452-Cornell_WinterOatPeaIntercrop_2024_Ithaca-PLOT_98 | B9: WOP_2026_selections
A10: NC21-6610-Cornell_WinterOatPeaIntercrop_2024_Ithaca-PLOT_99 | B10: WOP_2026_selections
A11: NF99414-Cornell_WinterOatPeaIntercrop_2024_Ithaca-PLOT_378 | B11: WOP_2026_selections
A12: NF13-4083-4_6-Cornell_WinterOatPeaIntercrop_2024_Ithaca-PLOT_83 | B12: WOP_2026_selections
... A53: PA7617-3658-Cornell_WinterOatPeaIntercrop_2024_Ithaca-PLOT_202 | B53: WOP_2026_selections

Sheet Sheet6
A1: AURORA-Cornell_WinterOatPeaIntercrop_2024_Ithaca-PLOT_24 | B1: WOP_2026_selections
A2: FLLA17088-61-Cornell_WinterOatPeaIntercrop_2024_Ithaca-PLOT_339 | B2: WOP_2026_selections
A3: FLLA17088-77-Cornell_WinterOatPeaIntercrop_2024_Ithaca-PLOT_48 | B3: WOP_2026_selections
A4: GERARD224-Cornell_WinterOatPeaIntercrop_2024_Ithaca-PLOT_218 | B4: WOP_2026_selections
A5: Gerard 227-Cornell_WinterOatPeaIntercrop_2024_Ithaca-PLOT_250 | B5: WOP_2026_selections
A6: HARRISON-Cornell_WinterOatPeaIntercrop_2024_Ithaca-PLOT_56 | B6: WOP_2026_selections
A7: HORIZON201-Cornell_WinterOatPeaIntercrop_2024_Ithaca-PLOT_199 | B7: WOP_2026_selections
A8: LA17069SBSS-2-1-Cornell_WinterOatPeaIntercrop_2024_Ithaca-PLOT_244 | B8: WOP_2026_selections
A9: LA17129SBSS-8-1-Cornell_WinterOatPeaIntercrop_2024_Ithaca-PLOT_165 | B9: WOP_2026_selections
A10: LA17153SBSS-46-1-Cornell_WinterOatPeaIntercrop_2024_Ithaca-PLOT_118 | B10: WOP_2026_selections
A11: NC17-6440-Cornell_WinterOatPeaIntercrop_2024_Ithaca-PLOT_306 | B11: WOP_2026_selections
A12: NC19-3542-Cornell_WinterOatPeaIntercrop_2024_Ithaca-PLOT_261 | B12: WOP_2026_selections
... A94: TX19CAS0058-Cornell_WinterOatPeaIntercrop_2024_Ithaca-PLOT_280 | B94: WOP_2026_not_selected

Sheet Sheet7
A1: Seedlot | B1: box | C1: g | F1: Seedlot_Name | G1: Current_Weight | H1: Quality
A2: NF502_5-Cornell_WinterOatPeaIntercrop_2024_Ithaca-PLOT_3 | B2: WOP_2026_not_selected | C2: =VLOOKUP(A2,$F$2:$G$101,2,FALSE) -> 762 | F2: AURORA-Cornell_WinterOatPeaIntercrop_2024_Ithaca-PLOT_24 | G2: 539.5
A3: NF12AS-91-4_1-Cornell_WinterOatPeaIntercrop_2024_Ithaca-PLOT_22 | B3: WOP_2026_not_selected | C3: =VLOOKUP(A3,$F$2:$G$101,2,FALSE) -> 815 | F3: Clav 4476-Cornell_WinterOatPeaIntercrop_2024_Ithaca-PLOT_240 | G3: 733
A4: NF05424_2-Cornell_WinterOatPeaIntercrop_2024_Ithaca-PLOT_25 | B4: WOP_2026_not_selected | C4: =VLOOKUP(A4,$F$2:$G$101,2,FALSE) -> 558 | F4: Clav 6982-Cornell_WinterOatPeaIntercrop_2024_Ithaca-PLOT_235 | G4: 585
A5: FLLA17069-52-Cornell_WinterOatPeaIntercrop_2024_Ithaca-PLOT_30 | B5: WOP_2026_not_selected | C5: =VLOOKUP(A5,$F$2:$G$101,2,FALSE) -> 876 | F5: Clav 7618-Cornell_WinterOatPeaIntercrop_2024_Ithaca-PLOT_123 | G5: 436
A6: FLLA17069-53-Cornell_WinterOatPeaIntercrop_2024_Ithaca-PLOT_34 | B6: WOP_2026_not_selected | C6: =VLOOKUP(A6,$F$2:$G$101,2,FALSE) -> 789 | F6: FLLA11019-8-Cornell_WinterOatPeaIntercrop_2024_Ithaca-PLOT_356 | G6: 714
A7: SCLA17031SBSS-4-1-Cornell_WinterOatPeaIntercrop_2024_Ithaca-PLOT_36 | B7: WOP_2026_not_selected | C7: =VLOOKUP(A7,$F$2:$G$101,2,FALSE) -> 847 | F7: FLLA16083-25-Cornell_WinterOatPeaIntercrop_2024_Ithaca-PLOT_351 | G7: 640
A8: Savage-Cornell_WinterOatPeaIntercrop_2024_Ithaca-PLOT_43 | B8: WOP_2026_not_selected | C8: =VLOOKUP(A8,$F$2:$G$101,2,FALSE) -> 797 | F8: FLLA17069-52-Cornell_WinterOatPeaIntercrop_2024_Ithaca-PLOT_30 | G8: 876
A9: NC21-6505-Cornell_WinterOatPeaIntercrop_2024_Ithaca-PLOT_63 | B9: WOP_2026_not_selected | C9: =VLOOKUP(A9,$F$2:$G$101,2,FALSE) -> 725 | F9: FLLA17069-53-Cornell_WinterOatPeaIntercrop_2024_Ithaca-PLOT_34 | G9: 789
A10: NF13-4124-4_3-Cornell_WinterOatPeaIntercrop_2024_Ithaca-PLOT_62 | B10: WOP_2026_not_selected | C10: =VLOOKUP(A10,$F$2:$G$101,2,FALSE) -> 587 | F10: FLLA17069-54-Cornell_WinterOatPeaIntercrop_2024_Ithaca-PLOT_102 | G10: 505
A11: LA15015SB-S50-Cornell_WinterOatPeaIntercrop_2024_Ithaca-PLOT_89 | B11: WOP_2026_not_selected | C11: =VLOOKUP(A11,$F$2:$G$101,2,FALSE) -> 763 | F11: FLLA17069-65-Cornell_WinterOatPeaIntercrop_2024_Ithaca-PLOT_113 | G11: 696
A12: NF99401_1-1-Cornell_WinterOatPeaIntercrop_2024_Ithaca-PLOT_95 | B12: WOP_2026_not_selected | C12: =VLOOKUP(A12,$F$2:$G$101,2,FALSE) -> 651 | F12: FLLA17088-61-Cornell_WinterOatPeaIntercrop_2024_Ithaca-PLOT_339 | G12: 499.4
A13: FLLA17069-54-Cornell_WinterOatPeaIntercrop_2024_Ithaca-PLOT_102 | B13: WOP_2026_not_selected | C13: =VLOOKUP(A13,$F$2:$G$101,2,FALSE) -> 505 | F13: FLLA17088-77-Cornell_WinterOatPeaIntercrop_2024_Ithaca-PLOT_48 | G13: 704
... A101: FLLA17088-77-Cornell_WinterOatPeaIntercrop_2024_Ithaca-PLOT_8 | B101: discard | C101: =VLOOKUP(A101,$F$2:$G$101,2,FALSE) -> #N/A | F101: PA7617-3658-Cornell_WinterOatPeaIntercrop_2024_Ithaca-PLOT_202 | G101: 733
A102: NC20-4452-Cornell_WinterOatPeaIntercrop_2024_Ithaca-PLOT_6 | B102: discard | C102: =VLOOKUP(A102,$F$2:$G$101,2,FALSE) -> #N/A
A103: TX18OCS9125-Cornell_WinterOatPeaIntercrop_2024_Ithaca-PLOT_9 | B103: discard | C103: =VLOOKUP(A103,$F$2:$G$101,2,FALSE) -> #N/A
A104: NO_OATS_PLANTED-Cornell_WinterOatPeaIntercrop_2024_Ithaca-PLOT_11 | B104: discard | C104: =VLOOKUP(A104,$F$2:$G$101,2,FALSE) -> #N/A
A105: NC21-6429-Cornell_WinterOatPeaIntercrop_2024_Ithaca-PLOT_15 | B105: discard | C105: =VLOOKUP(A105,$F$2:$G$101,2,FALSE) -> #N/A
A106: OKAY-Cornell_WinterOatPeaIntercrop_2024_Ithaca-PLOT_13 | B106: discard | C106: =VLOOKUP(A106,$F$2:$G$101,2,FALSE) -> #N/A
A107: NO_OATS_PLANTED-Cornell_WinterOatPeaIntercrop_2024_Ithaca-PLOT_12 | B107: discard | C107: =VLOOKUP(A107,$F$2:$G$101,2,FALSE) -> #N/A
A108: NO_OATS_PLANTED-Cornell_WinterOatPeaIntercrop_2024_Ithaca-PLOT_18 | B108: discard | C108: =VLOOKUP(A108,$F$2:$G$101,2,FALSE) -> #N/A
A109: Clav 6982-Cornell_WinterOatPeaIntercrop_2024_Ithaca-PLOT_19 | B109: discard | C109: =VLOOKUP(A109,$F$2:$G$101,2,FALSE) -> #N/A
A110: NO_OATS_PLANTED-Cornell_WinterOatPeaIntercrop_2024_Ithaca-PLOT_17 | B110: discard | C110: =VLOOKUP(A110,$F$2:$G$101,2,FALSE) -> #N/A
A111: Clav 6982-Cornell_WinterOatPeaIntercrop_2024_Ithaca-PLOT_20 | B111: discard | C111: =VLOOKUP(A111,$F$2:$G$101,2,FALSE) -> #N/A
A112: NF12AS-91-4_1-Cornell_WinterOatPeaIntercrop_2024_Ithaca-PLOT_21 | B112: discard | C112: =VLOOKUP(A112,$F$2:$G$101,2,FALSE) -> #N/A
A113: NF13-4214-4_5-Cornell_WinterOatPeaIntercrop_2024_Ithaca-PLOT_27 | B113: discard | C113: =VLOOKUP(A113,$F$2:$G$101,2,FALSE) -> #N/A
... A380: AURORA-Cornell_WinterOatPeaIntercrop_2024_Ithaca-PLOT_23 | B380: discard | C380: =VLOOKUP(A380,$F$2:$G$101,2,FALSE) -> #N/A

Sheet Sheet8
A1: Seedlot_Name | B1: Content_Name | C1: Content_type | D1: Material_type | E1: Description | F1: Box_Name | G1: Current_Count | H1: Current_Weight | I1: Quality
A2: AURORA-Cornell_WinterOatPeaIntercrop_2024_Ithaca-PLOT_24 | B2: AURORA | C2: accession | D2: seed | F2: WOP_2026_selections | G2: NA | H2: 539.5
A3: Clav 4476-Cornell_WinterOatPeaIntercrop_2024_Ithaca-PLOT_240 | B3: Clav 4476 | C3: accession | F3: 2 | G3: NA | H3: 733
A4: Clav 6982-Cornell_WinterOatPeaIntercrop_2024_Ithaca-PLOT_235 | B4: Clav 6982 | C4: accession | F4: 2 | G4: NA | H4: 585
A5: Clav 7618-Cornell_WinterOatPeaIntercrop_2024_Ithaca-PLOT_123 | B5: Clav 7618 | C5: accession | F5: 2 | G5: NA | H5: 436
A6: FLLA11019-8-Cornell_WinterOatPeaIntercrop_2024_Ithaca-PLOT_356 | B6: FLLA11019-8 | C6: accession | F6: 2 | G6: NA | H6: 714
A7: FLLA16083-25-Cornell_WinterOatPeaIntercrop_2024_Ithaca-PLOT_351 | B7: FLLA16083-25 | C7: accession | F7: 2 | G7: NA | H7: 640
A8: FLLA17069-52-Cornell_WinterOatPeaIntercrop_2024_Ithaca-PLOT_30 | B8: FLLA17069-52 | C8: accession | F8: 2 | G8: NA | H8: 876
A9: FLLA17069-53-Cornell_WinterOatPeaIntercrop_2024_Ithaca-PLOT_34 | B9: FLLA17069-53 | C9: accession | F9: 2 | G9: NA | H9: 789
A10: FLLA17069-54-Cornell_WinterOatPeaIntercrop_2024_Ithaca-PLOT_102 | B10: FLLA17069-54 | C10: accession | F10: 2 | G10: NA | H10: 505
A11: FLLA17069-65-Cornell_WinterOatPeaIntercrop_2024_Ithaca-PLOT_113 | B11: FLLA17069-65 | C11: accession | F11: 2 | G11: NA | H11: 696
A12: FLLA17088-61-Cornell_WinterOatPeaIntercrop_2024_Ithaca-PLOT_339 | B12: FLLA17088-61 | C12: accession | F12: WOP_2026_selections | G12: NA | H12: 499.4
A13: FLLA17088-77-Cornell_WinterOatPeaIntercrop_2024_Ithaca-PLOT_48 | B13: FLLA17088-77 | C13: accession | F13: WOP_2026_selections | G13: NA | H13: 704
A14: GERARD224-Cornell_WinterOatPeaIntercrop_2024_Ithaca-PLOT_218 | B14: GERARD224 | C14: accession | F14: WOP_2026_selections | G14: NA | H14: 617.1
A15: Gerard 227-Cornell_WinterOatPeaIntercrop_2024_Ithaca-PLOT_250 | B15: Gerard 227 | C15: accession | F15: WOP_2026_selections | G15: NA | H15: 867.9
A16: HARRISON-Cornell_WinterOatPeaIntercrop_2024_Ithaca-PLOT_56 | B16: HARRISON | C16: accession | F16: WOP_2026_selections | G16: NA | H16: 556.2
A17: HORIZON201-Cornell_WinterOatPeaIntercrop_2024_Ithaca-PLOT_199 | B17: HORIZON201 | C17: accession | F17: WOP_2026_selections | G17: NA | H17: 600.3
A18: Horizon 578-Cornell_WinterOatPeaIntercrop_2024_Ithaca-PLOT_282 | B18: Horizon 578 | C18: accession | F18: 2 | G18: NA | H18: 710
A19: Juggernaut-Cornell_WinterOatPeaIntercrop_2024_Ithaca-PLOT_327 | B19: Juggernaut | C19: accession | F19: 2 | G19: NA | H19: 732
A20: LA08039SBSBS-56-A1-Cornell_WinterOatPeaIntercrop_2024_Ithaca-PLOT_207 | B20: LA08039SBSBS-56-A1 | C20: accession | F20: 2 | G20: NA | H20: 823
A21: LA15015SB-S50-Cornell_WinterOatPeaIntercrop_2024_Ithaca-PLOT_89 | B21: LA15015SB-S50 | C21: accession | F21: 2 | G21: NA | H21: 763
A22: LA17069SBSS-2-1-Cornell_WinterOatPeaIntercrop_2024_Ithaca-PLOT_244 | B22: LA17069SBSS-2-1 | C22: accession | F22: WOP_2026_selections | G22: NA | H22: 682.6
A23: LA17075SBSS-29-1-Cornell_WinterOatPeaIntercrop_2024_Ithaca-PLOT_294 | B23: LA17075SBSS-29-1 | C23: accession | F23: 2 | G23: NA | H23: 798
A24: LA17089SBS-45-1-1-Cornell_WinterOatPeaIntercrop_2024_Ithaca-PLOT_223 | B24: LA17089SBS-45-1-1 | C24: accession | F24: 2 | G24: NA | H24: 860
A25: LA17129SBSS-8-1-Cornell_WinterOatPeaIntercrop_2024_Ithaca-PLOT_165 | B25: LA17129SBSS-8-1 | C25: accession | F25: WOP_2026_selections | G25: NA | H25: 608.5
A26: LA17153SBSS-46-1-Cornell_WinterOatPeaIntercrop_2024_Ithaca-PLOT_118 | B26: LA17153SBSS-46-1 | C26: accession | F26: WOP_2026_selections | G26: NA | H26: 433
A27: LA17153SBSS-55-1-Cornell_WinterOatPeaIntercrop_2024_Ithaca-PLOT_299 | B27: LA17153SBSS-55-1 | C27: accession | F27: 2 | G27: NA | H27: 693
A28: LA99016-Cornell_WinterOatPeaIntercrop_2024_Ithaca-PLOT_238 | B28: LA99016 | C28: accession | F28: 2 | G28: NA | H28: 997
A29: NC09-4503N-Cornell_WinterOatPeaIntercrop_2024_Ithaca-PLOT_149 | B29: NC09-4503N | C29: accession | F29: 2 | G29: NA | H29: 764
A30: NC17-6440-Cornell_WinterOatPeaIntercrop_2024_Ithaca-PLOT_306 | B30: NC17-6440 | C30: accession | F30: WOP_2026_selections | G30: NA | H30: 570.7
A31: NC18-5877N-Cornell_WinterOatPeaIntercrop_2024_Ithaca-PLOT_175 | B31: NC18-5877N | C31: accession | F31: 2 | G31: NA | H31: 687
A32: NC19-3542-Cornell_WinterOatPeaIntercrop_2024_Ithaca-PLOT_261 | B32: NC19-3542 | C32: accession | F32: WOP_2026_selections | G32: NA | H32: 704.6
A33: NC20-4402-Cornell_WinterOatPeaIntercrop_2024_Ithaca-PLOT_142 | B33: NC20-4402 | C33: accession | F33: WOP_2026_selections | G33: NA | H33: 574
A34: NC20-4452-Cornell_WinterOatPeaIntercrop_2024_Ithaca-PLOT_98 | B34: NC20-4452 | C34: accession | F34: WOP_2026_selections | G34: NA | H34: 979.3
A35: NC20-4526-Cornell_WinterOatPeaIntercrop_2024_Ithaca-PLOT_32 | B35: NC20-4526 | C35: accession | F35: WOP_2026_selections | G35: NA | H35: 888.9
A36: NC20-4551-Cornell_WinterOatPeaIntercrop_2024_Ithaca-PLOT_50 | B36: NC20-4551 | C36: accession | F36: WOP_2026_selections | G36: NA | H36: 489.8
A37: NC20-4700-Cornell_WinterOatPeaIntercrop_2024_Ithaca-PLOT_364 | B37: NC20-4700 | C37: accession | F37: WOP_2026_selections | G37: NA | H37: 555.2
A38: NC20-4702-Cornell_WinterOatPeaIntercrop_2024_Ithaca-PLOT_192 | B38: NC20-4702 | C38: accession | F38: WOP_2026_selections | G38: NA | H38: 669.7
A39: NC20-4795-Cornell_WinterOatPeaIntercrop_2024_Ithaca-PLOT_348 | B39: NC20-4795 | C39: accession | F39: 2 | G39: NA | H39: 739
A40: NC21-6429-Cornell_WinterOatPeaIntercrop_2024_Ithaca-PLOT_16 | B40: NC21-6429 | C40: accession | F40: WOP_2026_selections | G40: NA | H40: 707.9
...

Sheet Sheet9
A1: Seedlot | B1: box | C1: g
A2: NC21-6492-Cornell_WinterOatPeaIntercrop_2024_Ithaca-PLOT_128 | B2: WOP_2026_selections | C2: 86.5
A3: PA7617-3658-Cornell_WinterOatPeaIntercrop_2024_Ithaca-PLOT_54 | B3: WOP_2026_selections | C3: 110.2
A4: NF12AS-73-4_3-Cornell_WinterOatPeaIntercrop_2024_Ithaca-PLOT_242 | B4: WOP_2026_selections | C4: 134
A5: OZARK|POGI-Cornell_WinterOatPeaIntercrop_2024_Ithaca-PLOT_204 | B5: WOP_2026_selections | C5: 163.6
A6: NF13-4083-4_6-Cornell_WinterOatPeaIntercrop_2024_Ithaca-PLOT_83 | B6: WOP_2026_selections | C6: 337.7
A7: NF13-4214-4_5-Cornell_WinterOatPeaIntercrop_2024_Ithaca-PLOT_169 | B7: WOP_2026_selections | C7: 341.7
A8: NF99414-Cornell_WinterOatPeaIntercrop_2024_Ithaca-PLOT_378 | B8: WOP_2026_selections | C8: 364.3
A9: PA7617-3460-Cornell_WinterOatPeaIntercrop_2024_Ithaca-PLOT_212 | B9: WOP_2026_selections | C9: 425.7
A10: LA17153SBSS-46-1-Cornell_WinterOatPeaIntercrop_2024_Ithaca-PLOT_118 | B10: WOP_2026_selections | C10: 433
A11: Clav 7618-Cornell_WinterOatPeaIntercrop_2024_Ithaca-PLOT_123 | B11: WOP_2026_not_selected | C11: 436
A12: NC21-6576-Cornell_WinterOatPeaIntercrop_2024_Ithaca-PLOT_85 | B12: WOP_2026_selections | C12: 478.9
A13: NC20-4551-Cornell_WinterOatPeaIntercrop_2024_Ithaca-PLOT_50 | B13: WOP_2026_selections | C13: 489.8
... A380: AURORA-Cornell_WinterOatPeaIntercrop_2024_Ithaca-PLOT_23 | B380: discard | C380: 0

Sheet Sheet10
A1: box_id | B1: seed_id | C1: inventory_date | D1: inventory_person | E1: weight_gram
A2: WOP_2026_selections | B2: NC21-6492-Cornell_WinterOatPeaIntercrop_2024_Ithaca-PLOT_128 | C2: 2025-11-17 | D2: Peter | E2: 86.5
A3: WOP_2026_selections | B3: PA7617-3658-Cornell_WinterOatPeaIntercrop_2024_Ithaca-PLOT_54 | C3: 2025-11-17 | D3: Peter | E3: 110.2
A4: WOP_2026_selections | B4: NF12AS-73-4_3-Cornell_WinterOatPeaIntercrop_2024_Ithaca-PLOT_242 | C4: 2025-11-17 | D4: Peter | E4: 134
A5: WOP_2026_selections | B5: OZARK|POGI-Cornell_WinterOatPeaIntercrop_2024_Ithaca-PLOT_204 | C5: 2025-11-17 | D5: Peter | E5: 163.6
A6: WOP_2026_selections | B6: NF13-4083-4_6-Cornell_WinterOatPeaIntercrop_2024_Ithaca-PLOT_83 | C6: 2025-11-17 | D6: Peter | E6: 337.7
A7: WOP_2026_selections | B7: NF13-4214-4_5-Cornell_WinterOatPeaIntercrop_2024_Ithaca-PLOT_169 | C7: 2025-11-17 | D7: Peter | E7: 341.7
A8: WOP_2026_selections | B8: NF99414-Cornell_WinterOatPeaIntercrop_2024_Ithaca-PLOT_378 | C8: 2025-11-17 | D8: Peter | E8: 364.3
A9: WOP_2026_selections | B9: PA7617-3460-Cornell_WinterOatPeaIntercrop_2024_Ithaca-PLOT_212 | C9: 2025-11-17 | D9: Peter | E9: 425.7
A10: WOP_2026_selections | B10: LA17153SBSS-46-1-Cornell_WinterOatPeaIntercrop_2024_Ithaca-PLOT_118 | C10: 2025-11-17 | D10: Peter | E10: 433
A11: WOP_2026_not_selected | B11: Clav 7618-Cornell_WinterOatPeaIntercrop_2024_Ithaca-PLOT_123 | C11: 2025-11-17 | D11: Peter | E11: 436
A12: WOP_2026_selections | B12: NC21-6576-Cornell_WinterOatPeaIntercrop_2024_Ithaca-PLOT_85 | C12: 2025-11-17 | D12: Peter | E12: 478.9
A13: WOP_2026_selections | B13: NC20-4551-Cornell_WinterOatPeaIntercrop_2024_Ithaca-PLOT_50 | C13: 2025-11-17 | D13: Peter | E13: 489.8
... A380: discard | B380: AURORA-Cornell_WinterOatPeaIntercrop_2024_Ithaca-PLOT_23 | C380: 2025-11-17 | D380: Peter | E380: 0
